Workbook

Sheet SALES
F1: SALES | P1: SELLING PRICE | AC1: REVENUE
A2: DATE | B2: RICE | C2: ATTA | D2: TOOR DAL | E2: MOONG DAL | F2: URAD DAL | G2: SUGAR | H2: COOKING OIL | I2: GHEE | J2: MILK & DAIRY | K2: DRY FRUITS | L2: RICE | M2: ATTA | N2: TOOR DAL | O2: MOONG DAL | P2: URAD DAL | Q2: SUGAR | R2: COOKING OIL | S2: GHEE | T2: MILK & DAIRY | U2: DRY FRUITS | V2: RICE | W2: ATTA | X2: TOOR DAL | Y2: MOONG DAL | Z2: URAD DAL | AA2: SUGAR | AB2: COOKING OIL | AC2: GHEE | AD2: MILK & DAIRY | AE2: DRY FRUITS | AF2: TOTAL REVENUE | AG2: DATE
A3: =DATE(2023,4,1) -> 45017 | B3: 140 | C3: 110 | D3: 24 | E3: 16 | F3: 40 | G3: 70 | H3: 36 | I3: 20 | J3: 56 | K3: 10 | L3: 45 | M3: 41 | N3: 102 | O3: 110 | P3: 112 | Q3: 45 | R3: 165 | S3: 416 | T3: 60 | U3: 855 | V3: =B3*L3 -> 6300 | W3: =C3*M3 -> 4510 | X3: =D3*N3 -> 2448 | Y3: =E3*O3 -> 1760 | Z3: =F3*P3 -> 4480 | AA3: =G3*Q3 -> 3150 | AB3: =H3*R3 -> 5940 | AC3: =I3*S3 -> 8320 | ... AE3: =K3*U3 -> 8550 | AF3: =SUM(V3:AE3) -> 48818 | AG3: =DATE(2023,4,1) -> 45017
A4: =DATE(2023,4,2) -> 45018 | B4: 90 | C4: 80 | D4: 28 | E4: 14 | F4: 44 | G4: 48 | H4: 30 | I4: 10 | J4: 50 | K4: 6 | L4: 45 | M4: 41 | N4: 102 | O4: 110 | P4: 112 | Q4: 45 | R4: 165 | S4: 420 | T4: 60 | U4: 855 | V4: =B4*L4 -> 4050 | W4: =C4*M4 -> 3280 | X4: =D4*N4 -> 2856 | Y4: =E4*O4 -> 1540 | Z4: =F4*P4 -> 4928 | AA4: =G4*Q4 -> 2160 | AB4: =H4*R4 -> 4950 | AC4: =I4*S4 -> 4200 | ... AE4: =K4*U4 -> 5130 | AF4: =SUM(V4:AE4) -> 36094 | AG4: =DATE(2023,4,2) -> 45018
A5: =DATE(2023,4,3) -> 45019 | B5: 70 | C5: 50 | D5: 20 | E5: 20 | F5: 50 | G5: 40 | H5: 40 | I5: 8 | J5: 58 | K5: 4 | L5: 45 | M5: 41 | N5: 102 | O5: 110 | P5: 112 | Q5: 45 | R5: 165 | S5: 420 | T5: 60 | U5: 855 | V5: =B5*L5 -> 3150 | W5: =C5*M5 -> 2050 | X5: =D5*N5 -> 2040 | Y5: =E5*O5 -> 2200 | Z5: =F5*P5 -> 5600 | AA5: =G5*Q5 -> 1800 | AB5: =H5*R5 -> 6600 | AC5: =I5*S5 -> 3360 | ... AE5: =K5*U5 -> 3420 | AF5: =SUM(V5:AE5) -> 33700 | AG5: =DATE(2023,4,3) -> 45019
A6: =DATE(2023,4,4) -> 45020 | B6: 60 | C6: 40 | D6: 22 | E6: 16 | F6: 44 | G6: 42 | H6: 40 | I6: 10 | J6: 64 | K6: 6 | L6: 44 | M6: 41 | N6: 102 | O6: 110 | P6: 112 | Q6: 43 | R6: 165 | S6: 435 | T6: 60 | U6: 865 | V6: =B6*L6 -> 2640 | W6: =C6*M6 -> 1640 | X6: =D6*N6 -> 2244 | Y6: =E6*O6 -> 1760 | Z6: =F6*P6 -> 4928 | AA6: =G6*Q6 -> 1806 | AB6: =H6*R6 -> 6600 | AC6: =I6*S6 -> 4350 | ... AE6: =K6*U6 -> 5190 | AF6: =SUM(V6:AE6) -> 34998 | AG6: =DATE(2023,4,4) -> 45020
A7: =DATE(2023,4,5) -> 45021 | B7: 66 | C7: 36 | D7: 18 | E7: 14 | F7: 40 | G7: 48 | H7: 38 | I7: 11 | J7: 75 | K7: 10 | L7: 44 | M7: 41 | N7: 102 | O7: 110 | P7: 112 | Q7: 43 | R7: 165 | S7: 435 | T7: 60 | U7: 865 | V7: =B7*L7 -> 2904 | W7: =C7*M7 -> 1476 | X7: =D7*N7 -> 1836 | Y7: =E7*O7 -> 1540 | Z7: =F7*P7 -> 4480 | AA7: =G7*Q7 -> 2064 | AB7: =H7*R7 -> 6270 | AC7: =I7*S7 -> 4785 | ... AE7: =K7*U7 -> 8650 | AF7: =SUM(V7:AE7) -> 38505 | AG7: =DATE(2023,4,5) -> 45021
A8: =DATE(2023,4,6) -> 45022 | B8: 20 | C8: 24 | D8: 8 | E8: 8 | F8: 4 | G8: 10 | H8: 8 | I8: 4 | J8: 60 | K8: 0 | L8: 44 | M8: 41 | N8: 102 | O8: 110 | P8: 112 | Q8: 43 | R8: 165 | S8: 435 | T8: 60 | U8: 865 | V8: =B8*L8 -> 880 | W8: =C8*M8 -> 984 | X8: =D8*N8 -> 816 | Y8: =E8*O8 -> 880 | Z8: =F8*P8 -> 448 | AA8: =G8*Q8 -> 430 | AB8: =H8*R8 -> 1320 | AC8: =I8*S8 -> 1740 | ... AE8: =K8*U8 -> 0 | AF8: =SUM(V8:AE8) -> 11098 | AG8: =DATE(2023,4,6) -> 45022
A9: =DATE(2023,4,7) -> 45023 | B9: 40 | C9: 20 | D9: 8 | E9: 6 | F9: 8 | G9: 8 | H9: 6 | I9: 2 | J9: 60 | K9: 2 | L9: 46 | M9: 41 | N9: 104 | O9: 110 | P9: 112 | Q9: 43 | R9: 162 | S9: 435 | T9: 60 | U9: 865 | V9: =B9*L9 -> 1840 | W9: =C9*M9 -> 820 | X9: =D9*N9 -> 832 | Y9: =E9*O9 -> 660 | Z9: =F9*P9 -> 896 | AA9: =G9*Q9 -> 344 | AB9: =H9*R9 -> 972 | AC9: =I9*S9 -> 870 | ... AE9: =K9*U9 -> 1730 | AF9: =SUM(V9:AE9) -> 12564 | AG9: =DATE(2023,4,7) -> 45023
A10: =DATE(2023,4,8) -> 45024 | B10: 40 | C10: 24 | D10: 8 | E10: 6 | F10: 6 | G10: 10 | H10: 8 | I10: 4 | J10: 59 | K10: 4 | L10: 44 | M10: 42 | N10: 104 | O10: 110 | P10: 112 | Q10: 43 | R10: 162 | S10: 435 | T10: 60 | U10: 865 | V10: =B10*L10 -> 1760 | W10: =C10*M10 -> 1008 | X10: =D10*N10 -> 832 | Y10: =E10*O10 -> 660 | Z10: =F10*P10 -> 672 | AA10: =G10*Q10 -> 430 | AB10: =H10*R10 -> 1296 | AC10: =I10*S10 -> 1740 | ... AE10: =K10*U10 -> 3460 | AF10: =SUM(V10:AE10) -> 15398 | AG10: =DATE(2023,4,8) -> 45024
A11: =DATE(2023,4,9) -> 45025 | B11: 60 | C11: 30 | D11: 6 | E11: 4 | F11: 4 | G11: 6 | H11: 6 | I11: 4 | J11: 80 | K11: 4 | L11: 44 | M11: 42 | N11: 104 | O11: 110 | P11: 112 | Q11: 43 | R11: 162 | S11: 435 | T11: 60 | U11: 865 | V11: =B11*L11 -> 2640 | W11: =C11*M11 -> 1260 | X11: =D11*N11 -> 624 | Y11: =E11*O11 -> 440 | Z11: =F11*P11 -> 448 | AA11: =G11*Q11 -> 258 | AB11: =H11*R11 -> 972 | AC11: =I11*S11 -> 1740 | ... AE11: =K11*U11 -> 3460 | AF11: =SUM(V11:AE11) -> 16642 | AG11: =DATE(2023,4,9) -> 45025
A12: =DATE(2023,4,10) -> 45026 | B12: 56 | C12: 32 | D12: 8 | E12: 6 | F12: 4 | G12: 8 | H12: 8 | I12: 0 | J12: 55 | K12: 0 | L12: 44 | M12: 42 | N12: 104 | O12: 110 | P12: 112 | Q12: 43 | R12: 162 | S12: 435 | T12: 60 | U12: 865 | V12: =B12*L12 -> 2464 | W12: =C12*M12 -> 1344 | X12: =D12*N12 -> 832 | Y12: =E12*O12 -> 660 | Z12: =F12*P12 -> 448 | AA12: =G12*Q12 -> 344 | AB12: =H12*R12 -> 1296 | AC12: =I12*S12 -> 0 | ... AE12: =K12*U12 -> 0 | AF12: =SUM(V12:AE12) -> 10688 | AG12: =DATE(2023,4,10) -> 45026
A13: =DATE(2023,4,11) -> 45027 | B13: 48 | C13: 24 | D13: 6 | E13: 8 | F13: 6 | G13: 8 | H13: 6 | I13: 2 | J13: 56 | K13: 0 | L13: 42 | M13: 42 | N13: 104 | O13: 110 | P13: 108 | Q13: 43 | R13: 158 | S13: 435 | T13: 60 | U13: 865 | V13: =B13*L13 -> 2016 | W13: =C13*M13 -> 1008 | X13: =D13*N13 -> 624 | Y13: =E13*O13 -> 880 | Z13: =F13*P13 -> 648 | AA13: =G13*Q13 -> 344 | AB13: =H13*R13 -> 948 | AC13: =I13*S13 -> 870 | ... AE13: =K13*U13 -> 0 | AF13: =SUM(V13:AE13) -> 10698 | AG13: =DATE(2023,4,11) -> 45027
A14: =DATE(2023,4,12) -> 45028 | B14: 48 | C14: 28 | D14: 8 | E14: 8 | F14: 8 | G14: 6 | H14: 6 | I14: 2 | J14: 58 | K14: 0 | L14: 42 | M14: 42 | N14: 104 | O14: 110 | P14: 108 | Q14: 43 | R14: 158 | S14: 435 | T14: 60 | U14: 865 | V14: =B14*L14 -> 2016 | W14: =C14*M14 -> 1176 | X14: =D14*N14 -> 832 | Y14: =E14*O14 -> 880 | Z14: =F14*P14 -> 864 | AA14: =G14*Q14 -> 258 | AB14: =H14*R14 -> 948 | AC14: =I14*S14 -> 870 | ... AE14: =K14*U14 -> 0 | AF14: =SUM(V14:AE14) -> 11324 | AG14: =DATE(2023,4,12) -> 45028
A15: =DATE(2023,4,13) -> 45029 | B15: 50 | C15: 28 | D15: 6 | E15: 8 | F15: 6 | G15: 10 | H15: 4 | I15: 0 | J15: 60 | K15: 0 | L15: 42 | M15: 42 | N15: 104 | O15: 110 | P15: 108 | Q15: 43 | R15: 158 | S15: 435 | T15: 60 | U15: 865 | V15: =B15*L15 -> 2100 | W15: =C15*M15 -> 1176 | X15: =D15*N15 -> 624 | Y15: =E15*O15 -> 880 | Z15: =F15*P15 -> 648 | AA15: =G15*Q15 -> 430 | AB15: =H15*R15 -> 632 | AC15: =I15*S15 -> 0 | ... AE15: =K15*U15 -> 0 | AF15: =SUM(V15:AE15) -> 10090 | AG15: =DATE(2023,4,13) -> 45029
A16: =DATE(2023,4,14) -> 45030 | B16: 106 | C16: 34 | D16: 12 | E16: 8 | F16: 10 | G16: 12 | H16: 8 | I16: 2 | J16: 65 | K16: 0 | L16: 44 | M16: 41 | N16: 108 | O16: 110 | P16: 111 | Q16: 43 | R16: 158 | S16: 435 | T16: 60 | U16: 865 | V16: =B16*L16 -> 4664 | W16: =C16*M16 -> 1394 | X16: =D16*N16 -> 1296 | Y16: =E16*O16 -> 880 | Z16: =F16*P16 -> 1110 | AA16: =G16*Q16 -> 516 | AB16: =H16*R16 -> 1264 | AC16: =I16*S16 -> 870 | ... AE16: =K16*U16 -> 0 | AF16: =SUM(V16:AE16) -> 15894 | AG16: =DATE(2023,4,14) -> 45030
A17: =DATE(2023,4,15) -> 45031 | B17: 42 | C17: 24 | D17: 6 | E17: 10 | F17: 8 | G17: 4 | H17: 4 | I17: 0 | J17: 57 | K17: 0 | L17: 44 | M17: 41 | N17: 108 | O17: 110 | P17: 111 | Q17: 43 | R17: 158 | S17: 435 | T17: 60 | U17: 865 | V17: =B17*L17 -> 1848 | W17: =C17*M17 -> 984 | X17: =D17*N17 -> 648 | Y17: =E17*O17 -> 1100 | Z17: =F17*P17 -> 888 | AA17: =G17*Q17 -> 172 | AB17: =H17*R17 -> 632 | AC17: =I17*S17 -> 0 | ... AE17: =K17*U17 -> 0 | AF17: =SUM(V17:AE17) -> 9692 | AG17: =DATE(2023,4,15) -> 45031
A18: =DATE(2023,4,16) -> 45032 | B18: 40 | C18: 26 | D18: 10 | E18: 10 | F18: 10 | G18: 4 | H18: 6 | I18: 0 | J18: 54 | K18: 1 | L18: 44 | M18: 41 | N18: 108 | O18: 110 | P18: 111 | Q18: 43 | R18: 158 | S18: 435 | T18: 60 | U18: 865 | V18: =B18*L18 -> 1760 | W18: =C18*M18 -> 1066 | X18: =D18*N18 -> 1080 | Y18: =E18*O18 -> 1100 | Z18: =F18*P18 -> 1110 | AA18: =G18*Q18 -> 172 | AB18: =H18*R18 -> 948 | AC18: =I18*S18 -> 0 | ... AE18: =K18*U18 -> 865 | AF18: =SUM(V18:AE18) -> 11341 | AG18: =DATE(2023,4,16) -> 45032
A19: =DATE(2023,4,17) -> 45033 | B19: 52 | C19: 20 | D19: 4 | E19: 2 | F19: 6 | G19: 4 | H19: 2 | I19: 0 | J19: 53 | K19: 0 | L19: 45 | M19: 41 | N19: 108 | O19: 110 | P19: 111 | Q19: 43 | R19: 158 | S19: 435 | T19: 59 | U19: 865 | V19: =B19*L19 -> 2340 | W19: =C19*M19 -> 820 | X19: =D19*N19 -> 432 | Y19: =E19*O19 -> 220 | Z19: =F19*P19 -> 666 | AA19: =G19*Q19 -> 172 | AB19: =H19*R19 -> 316 | AC19: =I19*S19 -> 0 | ... AE19: =K19*U19 -> 0 | AF19: =SUM(V19:AE19) -> 8093 | AG19: =DATE(2023,4,17) -> 45033
A20: =DATE(2023,4,18) -> 45034 | B20: 40 | C20: 30 | D20: 4 | E20: 2 | F20: 2 | G20: 2 | H20: 0 | I20: 2 | J20: 55 | K20: 0 | L20: 45 | M20: 41 | N20: 108 | O20: 110 | P20: 111 | Q20: 44 | R20: 158 | S20: 435 | T20: 59 | U20: 865 | V20: =B20*L20 -> 1800 | W20: =C20*M20 -> 1230 | X20: =D20*N20 -> 432 | Y20: =E20*O20 -> 220 | Z20: =F20*P20 -> 222 | AA20: =G20*Q20 -> 88 | AB20: =H20*R20 -> 0 | AC20: =I20*S20 -> 870 | ... AE20: =K20*U20 -> 0 | AF20: =SUM(V20:AE20) -> 8107 | AG20: =DATE(2023,4,18) -> 45034
A21: =DATE(2023,4,19) -> 45035 | B21: 36 | C21: 20 | D21: 6 | E21: 2 | F21: 6 | G21: 4 | H21: 4 | I21: 2 | J21: 54 | K21: 0 | L21: 43 | M21: 41 | N21: 108 | O21: 110 | P21: 111 | Q21: 47 | R21: 158 | S21: 435 | T21: 59 | U21: 890 | V21: =B21*L21 -> 1548 | W21: =C21*M21 -> 820 | X21: =D21*N21 -> 648 | Y21: =E21*O21 -> 220 | Z21: =F21*P21 -> 666 | AA21: =G21*Q21 -> 188 | AB21: =H21*R21 -> 632 | AC21: =I21*S21 -> 870 | ... AE21: =K21*U21 -> 0 | AF21: =SUM(V21:AE21) -> 8778 | AG21: =DATE(2023,4,19) -> 45035
A22: =DATE(2023,4,20) -> 45036 | B22: 38 | C22: 18 | D22: 4 | E22: 6 | F22: 8 | G22: 6 | H22: 4 | I22: 2 | J22: 55 | K22: 2 | L22: 45 | M22: 41 | N22: 104 | O22: 113 | P22: 122 | Q22: 45 | R22: 158 | S22: 435 | T22: 59 | U22: 890 | V22: =B22*L22 -> 1710 | W22: =C22*M22 -> 738 | X22: =D22*N22 -> 416 | Y22: =E22*O22 -> 678 | Z22: =F22*P22 -> 976 | AA22: =G22*Q22 -> 270 | AB22: =H22*R22 -> 632 | AC22: =I22*S22 -> 870 | ... AE22: =K22*U22 -> 1780 | AF22: =SUM(V22:AE22) -> 11315 | AG22: =DATE(2023,4,20) -> 45036
A23: =DATE(2023,4,21) -> 45037 | B23: 48 | C23: 30 | D23: 8 | E23: 2 | F23: 2 | G23: 8 | H23: 6 | I23: 4 | J23: 50 | K23: 2 | L23: 45 | M23: 41 | N23: 104 | O23: 113 | P23: 122 | Q23: 45 | R23: 142 | S23: 440 | T23: 60 | U23: 895 | V23: =B23*L23 -> 2160 | W23: =C23*M23 -> 1230 | X23: =D23*N23 -> 832 | Y23: =E23*O23 -> 226 | Z23: =F23*P23 -> 244 | AA23: =G23*Q23 -> 360 | AB23: =H23*R23 -> 852 | AC23: =I23*S23 -> 1760 | ... AE23: =K23*U23 -> 1790 | AF23: =SUM(V23:AE23) -> 12454 | AG23: =DATE(2023,4,21) -> 45037
A24: =DATE(2023,4,22) -> 45038 | B24: 260 | C24: 90 | D24: 36 | E24: 26 | F24: 28 | G24: 94 | H24: 68 | I24: 18 | J24: 90 | K24: 6 | L24: 45 | M24: 41 | N24: 104 | O24: 113 | P24: 122 | Q24: 45 | R24: 142 | S24: 440 | T24: 60 | U24: 895 | V24: =B24*L24 -> 11700 | W24: =C24*M24 -> 3690 | X24: =D24*N24 -> 3744 | Y24: =E24*O24 -> 2938 | Z24: =F24*P24 -> 3416 | AA24: =G24*Q24 -> 4230 | AB24: =H24*R24 -> 9656 | AC24: =I24*S24 -> 7920 | ... AE24: =K24*U24 -> 5370 | AF24: =SUM(V24:AE24) -> 58064 | AG24: =DATE(2023,4,22) -> 45038
A25: =DATE(2023,4,23) -> 45039 | B25: 290 | C25: 116 | D25: 30 | E25: 20 | F25: 36 | G25: 100 | H25: 60 | I25: 20 | J25: 90 | K25: 10 | L25: 45 | M25: 41 | N25: 104 | O25: 113 | P25: 122 | Q25: 45 | R25: 130 | S25: 440 | T25: 60 | U25: 895 | V25: =B25*L25 -> 13050 | W25: =C25*M25 -> 4756 | X25: =D25*N25 -> 3120 | Y25: =E25*O25 -> 2260 | Z25: =F25*P25 -> 4392 | AA25: =G25*Q25 -> 4500 | AB25: =H25*R25 -> 7800 | AC25: =I25*S25 -> 8800 | ... AE25: =K25*U25 -> 8950 | AF25: =SUM(V25:AE25) -> 63028 | AG25: =DATE(2023,4,23) -> 45039
A26: =DATE(2023,4,24) -> 45040 | B26: 230 | C26: 96 | D26: 30 | E26: 18 | F26: 24 | G26: 54 | H26: 36 | I26: 22 | J26: 95 | K26: 11 | L26: 45 | M26: 41 | N26: 104 | O26: 113 | P26: 122 | Q26: 45 | R26: 130 | S26: 440 | T26: 60 | U26: 895 | V26: =B26*L26 -> 10350 | W26: =C26*M26 -> 3936 | X26: =D26*N26 -> 3120 | Y26: =E26*O26 -> 2034 | Z26: =F26*P26 -> 2928 | AA26: =G26*Q26 -> 2430 | AB26: =H26*R26 -> 4680 | AC26: =I26*S26 -> 9680 | ... AE26: =K26*U26 -> 9845 | AF26: =SUM(V26:AE26) -> 54703 | AG26: =DATE(2023,4,24) -> 45040
A27: =DATE(2023,4,25) -> 45041 | B27: 160 | C27: 60 | D27: 22 | E27: 10 | F27: 16 | G27: 40 | H27: 22 | I27: 20 | J27: 100 | K27: 12 | L27: 45 | M27: 41 | N27: 104 | O27: 113 | P27: 122 | Q27: 45 | R27: 130 | S27: 440 | T27: 60 | U27: 895 | V27: =B27*L27 -> 7200 | W27: =C27*M27 -> 2460 | X27: =D27*N27 -> 2288 | Y27: =E27*O27 -> 1130 | Z27: =F27*P27 -> 1952 | AA27: =G27*Q27 -> 1800 | AB27: =H27*R27 -> 2860 | AC27: =I27*S27 -> 8800 | ... AE27: =K27*U27 -> 10740 | AF27: =SUM(V27:AE27) -> 45230 | AG27: =DATE(2023,4,25) -> 45041
A28: =DATE(2023,4,26) -> 45042 | B28: 70 | C28: 16 | D28: 12 | E28: 8 | F28: 8 | G28: 12 | H28: 6 | I28: 2 | J28: 57 | K28: 0 | L28: 45 | M28: 41 | N28: 104 | O28: 113 | P28: 122 | Q28: 45 | R28: 130 | S28: 440 | T28: 60 | U28: 895 | V28: =B28*L28 -> 3150 | W28: =C28*M28 -> 656 | X28: =D28*N28 -> 1248 | Y28: =E28*O28 -> 904 | Z28: =F28*P28 -> 976 | AA28: =G28*Q28 -> 540 | AB28: =H28*R28 -> 780 | AC28: =I28*S28 -> 880 | ... AE28: =K28*U28 -> 0 | AF28: =SUM(V28:AE28) -> 12554 | AG28: =DATE(2023,4,26) -> 45042
A29: =DATE(2023,4,27) -> 45043 | B29: 210 | C29: 40 | D29: 18 | E29: 10 | F29: 16 | G29: 12 | H29: 20 | I29: 4 | J29: 55 | K29: 0 | L29: 45 | M29: 41 | N29: 104 | O29: 113 | P29: 122 | Q29: 45 | R29: 130 | S29: 440 | T29: 60 | U29: 895 | V29: =B29*L29 -> 9450 | W29: =C29*M29 -> 1640 | X29: =D29*N29 -> 1872 | Y29: =E29*O29 -> 1130 | Z29: =F29*P29 -> 1952 | AA29: =G29*Q29 -> 540 | AB29: =H29*R29 -> 2600 | AC29: =I29*S29 -> 1760 | ... AE29: =K29*U29 -> 0 | AF29: =SUM(V29:AE29) -> 24244 | AG29: =DATE(2023,4,27) -> 45043
A30: =DATE(2023,4,28) -> 45044 | B30: 260 | C30: 60 | D30: 30 | E30: 24 | F30: 24 | G30: 18 | H30: 28 | I30: 8 | J30: 65 | K30: 4 | L30: 45 | M30: 41 | N30: 104 | O30: 113 | P30: 122 | Q30: 45 | R30: 130 | S30: 440 | T30: 60 | U30: 880 | V30: =B30*L30 -> 11700 | W30: =C30*M30 -> 2460 | X30: =D30*N30 -> 3120 | Y30: =E30*O30 -> 2712 | Z30: =F30*P30 -> 2928 | AA30: =G30*Q30 -> 810 | AB30: =H30*R30 -> 3640 | AC30: =I30*S30 -> 3520 | ... AE30: =K30*U30 -> 3520 | AF30: =SUM(V30:AE30) -> 38310 | AG30: =DATE(2023,4,28) -> 45044
A31: =DATE(2023,4,29) -> 45045 | B31: 160 | C31: 24 | D31: 14 | E31: 16 | F31: 18 | G31: 10 | H31: 20 | I31: 4 | J31: 52 | K31: 2 | L31: 47 | M31: 41 | N31: 104 | O31: 113 | P31: 122 | Q31: 45 | R31: 130 | S31: 440 | T31: 60 | U31: 880 | V31: =B31*L31 -> 7520 | W31: =C31*M31 -> 984 | X31: =D31*N31 -> 1456 | Y31: =E31*O31 -> 1808 | Z31: =F31*P31 -> 2196 | AA31: =G31*Q31 -> 450 | AB31: =H31*R31 -> 2600 | AC31: =I31*S31 -> 1760 | ... AE31: =K31*U31 -> 1760 | AF31: =SUM(V31:AE31) -> 23654 | AG31: =DATE(2023,4,29) -> 45045
A32: =DATE(2023,4,30) -> 45046 | B32: 156 | C32: 26 | D32: 16 | E32: 10 | F32: 12 | G32: 14 | H32: 22 | I32: 2 | J32: 54 | K32: 0 | L32: 47 | M32: 41 | N32: 104 | O32: 113 | P32: 122 | Q32: 45 | R32: 141 | S32: 440 | T32: 60 | U32: 880 | V32: =B32*L32 -> 7332 | W32: =C32*M32 -> 1066 | X32: =D32*N32 -> 1664 | Y32: =E32*O32 -> 1130 | Z32: =F32*P32 -> 1464 | AA32: =G32*Q32 -> 630 | AB32: =H32*R32 -> 3102 | AC32: =I32*S32 -> 880 | ... AE32: =K32*U32 -> 0 | AF32: =SUM(V32:AE32) -> 20508 | AG32: =DATE(2023,4,30) -> 45046
A33: =DATE(2023,4,31) -> 45047 | B33: 130 | C33: 20 | D33: 12 | E33: 12 | F33: 14 | G33: 8 | H33: 16 | I33: 2 | J33: 55 | K33: 2 | L33: 47 | M33: 41 | N33: 105 | O33: 113 | P33: 118 | Q33: 45 | R33: 141 | S33: 440 | T33: 60 | U33: 880 | V33: =B33*L33 -> 6110 | W33: =C33*M33 -> 820 | X33: =D33*N33 -> 1260 | Y33: =E33*O33 -> 1356 | Z33: =F33*P33 -> 1652 | AA33: =G33*Q33 -> 360 | AB33: =H33*R33 -> 2256 | AC33: =I33*S33 -> 880 | ... AE33: =K33*U33 -> 1760 | AF33: =SUM(V33:AE33) -> 19754 | AG33: =DATE(2023,4,31) -> 45047
B34: =AVERAGE(B3:B33) -> 100.51613 | C34: =AVERAGE(C3:C33) -> 41.16129 | D34: =AVERAGE(D3:D33) -> 14.322581 | E34: =AVERAGE(E3:E33) -> 10.645161 | F34: =AVERAGE(F3:F33) -> 16.516129 | G34: =AVERAGE(G3:G33) -> 23.225806 | H34: =AVERAGE(H3:H33) -> 18.322581 | I34: =AVERAGE(I3:I33) -> 6.1612903 | ... U34: =AVERAGE(U3:U33) -> 874.35484 | V34: =SUM(V3:V33) -> 140152 | W34: =SUM(W3:W33) -> 52482 | X34: =SUM(X3:X33) -> 46116 | Y34: =SUM(Y3:Y33) -> 36786 | Z34: =SUM(Z3:Z33) -> 59226 | AA34: =SUM(AA3:AA33) -> 32046 | AB34: =SUM(AB3:AB33) -> 83994 | AC34: =SUM(AC3:AC33) -> 82965 | ... AF34: =SUM(AF3:AF33) -> 736340
B35: RICE | C35: ATTA | D35: TOOR DAL | E35: MOONG DAL | F35: URAD DAL | G35: SUGAR | H35: COOKING OIL | I35: GHEE | J35: MILK & DAIRY | K35: DRY FRUITS | V35: RICE | W35: ATTA | X35: TOOR DAL | Y35: MOONG DAL | Z35: URAD DAL | AA35: SUGAR | AB35: COOKING OIL | AC35: GHEE | AD35: MILK & DAIRY | AE35: DRY FRUITS | AF35: AVERAGE REVENUE | AG35: =SUM(AF3:AF33)/31 -> 23752.903
B36: =SUM(B3:B33) -> 3116 | C36: =SUM(C3:C33) -> 1276 | D36: =SUM(D3:D33) -> 444 | E36: =SUM(E3:E33) -> 330 | F36: =SUM(F3:F33) -> 512 | G36: =SUM(G3:G33) -> 720 | H36: =SUM(H3:H33) -> 568 | I36: =SUM(I3:I33) -> 191 | ... K36: =SUM(K3:K33) -> 98 | AF36: S.D | AG36: =STDEV(AF3:AF33) -> 16557.766
C37: SALES TREND | AF37: MIN | AG37: =MIN(AF3:AF33) -> 8093
AF38: MAX | AG38: =MAX(AF3:AF33) -> 63028

Sheet PURCHASE
F1: PURCHASE | P1: PURCHASE PRICE | Z1: EXPENDITURE | AF1: TOTAL EXPENDOTURE
A2: DATE | B2: RICE | C2: ATTA | D2: TOOR DAL | E2: MOONG DAL | F2: URAD DAL | G2: SUGAR | H2: COOKING OIL | I2: GHEE | J2: MILK & DAIRY | K2: DRY FRUITS | L2: RICE | M2: ATTA | N2: TOOR DAL | O2: MOONG DAL | P2: URAD DAL | Q2: SUGAR | R2: COOKING OIL | S2: GHEE | T2: MILK & DAIRY | U2: DRY FRUITS | V2: RICE | W2: ATTA | X2: TOOR DAL | Y2: MOONG DAL | Z2: URAD DAL | AA2: SUGAR | AB2: COOKING OIL | AC2: GHEE | AD2: MILK & DAIRY | AE2: DRY FRUITS
A3: =DATE(2023,4,1) -> 45017 | B3: 0 | C3: 0 | D3: 0 | E3: 0 | F3: 0 | G3: 0 | H3: 0 | I3: 0 | J3: 60 | K3: 44 | L3: =0.9*SALES!L3 -> 40.5 | M3: =0.92*SALES!M3 -> 37.72 | N3: =0.92*SALES!N3 -> 93.84 | O3: =0.9*SALES!O3 -> 99 | P3: =0.92*SALES!P3 -> 103.04 | Q3: =0.94*SALES!Q3 -> 42.3 | R3: =0.94*SALES!R3 -> 155.1 | S3: =0.9*SALES!S3 -> 374.4 | T3: =0.95*SALES!T3 -> 57 | U3: =0.82*SALES!U3 -> 701.1 | V3: =B3*L3 -> 0 | W3: =C3*M3 -> 0 | X3: =D3*N3 -> 0 | Y3: =E3*O3 -> 0 | Z3: =F3*P3 -> 0 | AA3: =G3*Q3 -> 0 | AB3: =H3*R3 -> 0 | AC3: =I3*S3 -> 0 | ... AE3: =K3*U3 -> 30848.4 | AF3: =sum(V3:AE3) -> 34268.4
A4: =DATE(2023,4,2) -> 45018 | B4: 0 | C4: 200 | D4: 0 | E4: 50 | F4: 0 | G4: 0 | H4: 0 | I4: 0 | J4: 56 | K4: 0 | L4: =0.9*SALES!L4 -> 40.5 | M4: =0.92*SALES!M4 -> 37.72 | N4: =0.92*SALES!N4 -> 93.84 | O4: =0.9*SALES!O4 -> 99 | P4: =0.92*SALES!P4 -> 103.04 | Q4: =0.94*SALES!Q4 -> 42.3 | R4: =0.94*SALES!R4 -> 155.1 | S4: =0.9*SALES!S4 -> 378 | T4: =0.95*SALES!T4 -> 57 | U4: =0.82*SALES!U4 -> 701.1 | V4: =B4*L4 -> 0 | W4: =C4*M4 -> 7544 | X4: =D4*N4 -> 0 | Y4: =E4*O4 -> 4950 | Z4: =F4*P4 -> 0 | AA4: =G4*Q4 -> 0 | AB4: =H4*R4 -> 0 | AC4: =I4*S4 -> 0 | ... AE4: =K4*U4 -> 0 | AF4: =sum(V4:AE4) -> 15686
A5: =DATE(2023,4,3) -> 45019 | B5: 0 | C5: 0 | D5: 50 | E5: 0 | F5: 50 | G5: 0 | H5: 60 | I5: 20 | J5: 60 | K5: 0 | L5: =0.9*SALES!L5 -> 40.5 | M5: =0.92*SALES!M5 -> 37.72 | N5: =0.92*SALES!N5 -> 93.84 | O5: =0.9*SALES!O5 -> 99 | P5: =0.92*SALES!P5 -> 103.04 | Q5: =0.94*SALES!Q5 -> 42.3 | R5: =0.94*SALES!R5 -> 155.1 | S5: =0.9*SALES!S5 -> 378 | T5: =0.95*SALES!T5 -> 57 | U5: =0.82*SALES!U5 -> 701.1 | V5: =B5*L5 -> 0 | W5: =C5*M5 -> 0 | X5: =D5*N5 -> 4692 | Y5: =E5*O5 -> 0 | Z5: =F5*P5 -> 5152 | AA5: =G5*Q5 -> 0 | AB5: =H5*R5 -> 9306 | AC5: =I5*S5 -> 7560 | ... AE5: =K5*U5 -> 0 | AF5: =sum(V5:AE5) -> 30130
A6: =DATE(2023,4,4) -> 45020 | B6: 0 | C6: 0 | D6: 0 | E6: 0 | F6: 50 | G6: 0 | H6: 60 | I6: 0 | J6: 64 | K6: 0 | L6: =0.9*SALES!L6 -> 39.6 | M6: =0.92*SALES!M6 -> 37.72 | N6: =0.92*SALES!N6 -> 93.84 | O6: =0.9*SALES!O6 -> 99 | P6: =0.92*SALES!P6 -> 103.04 | Q6: =0.94*SALES!Q6 -> 40.42 | R6: =0.94*SALES!R6 -> 155.1 | S6: =0.9*SALES!S6 -> 391.5 | T6: =0.95*SALES!T6 -> 57 | U6: =0.82*SALES!U6 -> 709.3 | V6: =B6*L6 -> 0 | W6: =C6*M6 -> 0 | X6: =D6*N6 -> 0 | Y6: =E6*O6 -> 0 | Z6: =F6*P6 -> 5152 | AA6: =G6*Q6 -> 0 | AB6: =H6*R6 -> 9306 | AC6: =I6*S6 -> 0 | ... AE6: =K6*U6 -> 0 | AF6: =sum(V6:AE6) -> 18106
A7: =DATE(2023,4,5) -> 45021 | B7: 0 | C7: 0 | D7: 0 | E7: 0 | F7: 0 | G7: 0 | H7: 0 | I7: 0 | J7: 80 | K7: 0 | L7: =0.9*SALES!L7 -> 39.6 | M7: =0.92*SALES!M7 -> 37.72 | N7: =0.92*SALES!N7 -> 93.84 | O7: =0.9*SALES!O7 -> 99 | P7: =0.92*SALES!P7 -> 103.04 | Q7: =0.94*SALES!Q7 -> 40.42 | R7: =0.94*SALES!R7 -> 155.1 | S7: =0.9*SALES!S7 -> 391.5 | T7: =0.95*SALES!T7 -> 57 | U7: =0.82*SALES!U7 -> 709.3 | V7: =B7*L7 -> 0 | W7: =C7*M7 -> 0 | X7: =D7*N7 -> 0 | Y7: =E7*O7 -> 0 | Z7: =F7*P7 -> 0 | AA7: =G7*Q7 -> 0 | AB7: =H7*R7 -> 0 | AC7: =I7*S7 -> 0 | ... AE7: =K7*U7 -> 0 | AF7: =sum(V7:AE7) -> 4560
A8: =DATE(2023,4,6) -> 45022 | B8: 0 | C8: 200 | D8: 50 | E8: 0 | F8: 50 | G8: 50 | H8: 0 | I8: 0 | J8: 70 | K8: 0 | L8: =0.9*SALES!L8 -> 39.6 | M8: =0.92*SALES!M8 -> 37.72 | N8: =0.92*SALES!N8 -> 93.84 | O8: =0.9*SALES!O8 -> 99 | P8: =0.92*SALES!P8 -> 103.04 | Q8: =0.94*SALES!Q8 -> 40.42 | R8: =0.94*SALES!R8 -> 155.1 | S8: =0.9*SALES!S8 -> 391.5 | T8: =0.95*SALES!T8 -> 57 | U8: =0.82*SALES!U8 -> 709.3 | V8: =B8*L8 -> 0 | W8: =C8*M8 -> 7544 | X8: =D8*N8 -> 4692 | Y8: =E8*O8 -> 0 | Z8: =F8*P8 -> 5152 | AA8: =G8*Q8 -> 2021 | AB8: =H8*R8 -> 0 | AC8: =I8*S8 -> 0 | ... AE8: =K8*U8 -> 0 | AF8: =sum(V8:AE8) -> 23399
A9: =DATE(2023,4,7) -> 45023 | B9: 0 | C9: 0 | D9: 0 | E9: 50 | F9: 0 | G9: 0 | H9: 0 | I9: 15 | J9: 60 | K9: 0 | L9: =0.9*SALES!L9 -> 41.4 | M9: =0.92*SALES!M9 -> 37.72 | N9: =0.92*SALES!N9 -> 95.68 | O9: =0.9*SALES!O9 -> 99 | P9: =0.92*SALES!P9 -> 103.04 | Q9: =0.94*SALES!Q9 -> 40.42 | R9: =0.94*SALES!R9 -> 152.28 | S9: =0.9*SALES!S9 -> 391.5 | T9: =0.95*SALES!T9 -> 57 | U9: =0.82*SALES!U9 -> 709.3 | V9: =B9*L9 -> 0 | W9: =C9*M9 -> 0 | X9: =D9*N9 -> 0 | Y9: =E9*O9 -> 4950 | Z9: =F9*P9 -> 0 | AA9: =G9*Q9 -> 0 | AB9: =H9*R9 -> 0 | AC9: =I9*S9 -> 5872.5 | ... AE9: =K9*U9 -> 0 | AF9: =sum(V9:AE9) -> 14242.5
A10: =DATE(2023,4,8) -> 45024 | B10: 0 | C10: 0 | D10: 0 | E10: 0 | F10: 0 | G10: 0 | H10: 0 | I10: 0 | J10: 60 | K10: 0 | L10: =0.9*SALES!L10 -> 39.6 | M10: =0.92*SALES!M10 -> 38.64 | N10: =0.92*SALES!N10 -> 95.68 | O10: =0.9*SALES!O10 -> 99 | P10: =0.92*SALES!P10 -> 103.04 | Q10: =0.94*SALES!Q10 -> 40.42 | R10: =0.94*SALES!R10 -> 152.28 | S10: =0.9*SALES!S10 -> 391.5 | T10: =0.95*SALES!T10 -> 57 | U10: =0.82*SALES!U10 -> 709.3 | V10: =B10*L10 -> 0 | W10: =C10*M10 -> 0 | X10: =D10*N10 -> 0 | Y10: =E10*O10 -> 0 | Z10: =F10*P10 -> 0 | AA10: =G10*Q10 -> 0 | AB10: =H10*R10 -> 0 | AC10: =I10*S10 -> 0 | ... AE10: =K10*U10 -> 0 | AF10: =sum(V10:AE10) -> 3420
A11: =DATE(2023,4,9) -> 45025 | B11: 0 | C11: 0 | D11: 0 | E11: 0 | F11: 0 | G11: 0 | H11: 20 | I11: 0 | J11: 80 | K11: 0 | L11: =0.9*SALES!L11 -> 39.6 | M11: =0.92*SALES!M11 -> 38.64 | N11: =0.92*SALES!N11 -> 95.68 | O11: =0.9*SALES!O11 -> 99 | P11: =0.92*SALES!P11 -> 103.04 | Q11: =0.94*SALES!Q11 -> 40.42 | R11: =0.94*SALES!R11 -> 152.28 | S11: =0.9*SALES!S11 -> 391.5 | T11: =0.95*SALES!T11 -> 57 | U11: =0.82*SALES!U11 -> 709.3 | V11: =B11*L11 -> 0 | W11: =C11*M11 -> 0 | X11: =D11*N11 -> 0 | Y11: =E11*O11 -> 0 | Z11: =F11*P11 -> 0 | AA11: =G11*Q11 -> 0 | AB11: =H11*R11 -> 3045.6 | AC11: =I11*S11 -> 0 | ... AE11: =K11*U11 -> 0 | AF11: =sum(V11:AE11) -> 7605.6
A12: =DATE(2023,4,10) -> 45026 | B12: 0 | C12: 0 | D12: 0 | E12: 0 | F12: 0 | G12: 0 | H12: 0 | I12: 0 | J12: 60 | K12: 0 | L12: =0.9*SALES!L12 -> 39.6 | M12: =0.92*SALES!M12 -> 38.64 | N12: =0.92*SALES!N12 -> 95.68 | O12: =0.9*SALES!O12 -> 99 | P12: =0.92*SALES!P12 -> 103.04 | Q12: =0.94*SALES!Q12 -> 40.42 | R12: =0.94*SALES!R12 -> 152.28 | S12: =0.9*SALES!S12 -> 391.5 | T12: =0.95*SALES!T12 -> 57 | U12: =0.82*SALES!U12 -> 709.3 | V12: =B12*L12 -> 0 | W12: =C12*M12 -> 0 | X12: =D12*N12 -> 0 | Y12: =E12*O12 -> 0 | Z12: =F12*P12 -> 0 | AA12: =G12*Q12 -> 0 | AB12: =H12*R12 -> 0 | AC12: =I12*S12 -> 0 | ... AE12: =K12*U12 -> 0 | AF12: =sum(V12:AE12) -> 3420
A13: =DATE(2023,4,11) -> 45027 | B13: 0 | C13: 0 | D13: 0 | E13: 0 | F13: 0 | G13: 0 | H13: 0 | I13: 0 | J13: 60 | K13: 0 | L13: =0.9*SALES!L13 -> 37.8 | M13: =0.92*SALES!M13 -> 38.64 | N13: =0.92*SALES!N13 -> 95.68 | O13: =0.9*SALES!O13 -> 99 | P13: =0.92*SALES!P13 -> 99.36 | Q13: =0.94*SALES!Q13 -> 40.42 | R13: =0.94*SALES!R13 -> 148.52 | S13: =0.9*SALES!S13 -> 391.5 | T13: =0.95*SALES!T13 -> 57 | U13: =0.82*SALES!U13 -> 709.3 | V13: =B13*L13 -> 0 | W13: =C13*M13 -> 0 | X13: =D13*N13 -> 0 | Y13: =E13*O13 -> 0 | Z13: =F13*P13 -> 0 | AA13: =G13*Q13 -> 0 | AB13: =H13*R13 -> 0 | AC13: =I13*S13 -> 0 | ... AE13: =K13*U13 -> 0 | AF13: =sum(V13:AE13) -> 3420
A14: =DATE(2023,4,12) -> 45028 | B14: 0 | C14: 0 | D14: 0 | E14: 0 | F14: 0 | G14: 0 | H14: 0 | I14: 0 | J14: 60 | K14: 0 | L14: =0.9*SALES!L14 -> 37.8 | M14: =0.92*SALES!M14 -> 38.64 | N14: =0.92*SALES!N14 -> 95.68 | O14: =0.9*SALES!O14 -> 99 | P14: =0.92*SALES!P14 -> 99.36 | Q14: =0.94*SALES!Q14 -> 40.42 | R14: =0.94*SALES!R14 -> 148.52 | S14: =0.9*SALES!S14 -> 391.5 | T14: =0.95*SALES!T14 -> 57 | U14: =0.82*SALES!U14 -> 709.3 | V14: =B14*L14 -> 0 | W14: =C14*M14 -> 0 | X14: =D14*N14 -> 0 | Y14: =E14*O14 -> 0 | Z14: =F14*P14 -> 0 | AA14: =G14*Q14 -> 0 | AB14: =H14*R14 -> 0 | AC14: =I14*S14 -> 0 | ... AE14: =K14*U14 -> 0 | AF14: =sum(V14:AE14) -> 3420
A15: =DATE(2023,4,13) -> 45029 | B15: 0 | C15: 0 | D15: 0 | E15: 0 | F15: 0 | G15: 0 | H15: 0 | I15: 0 | J15: 60 | K15: 0 | L15: =0.9*SALES!L15 -> 37.8 | M15: =0.92*SALES!M15 -> 38.64 | N15: =0.92*SALES!N15 -> 95.68 | O15: =0.9*SALES!O15 -> 99 | P15: =0.92*SALES!P15 -> 99.36 | Q15: =0.94*SALES!Q15 -> 40.42 | R15: =0.94*SALES!R15 -> 148.52 | S15: =0.9*SALES!S15 -> 391.5 | T15: =0.95*SALES!T15 -> 57 | U15: =0.82*SALES!U15 -> 709.3 | V15: =B15*L15 -> 0 | W15: =C15*M15 -> 0 | X15: =D15*N15 -> 0 | Y15: =E15*O15 -> 0 | Z15: =F15*P15 -> 0 | AA15: =G15*Q15 -> 0 | AB15: =H15*R15 -> 0 | AC15: =I15*S15 -> 0 | ... AE15: =K15*U15 -> 0 | AF15: =sum(V15:AE15) -> 3420
A16: =DATE(2023,4,14) -> 45030 | B16: 400 | C16: 100 | D16: 50 | E16: 50 | F16: 50 | G16: 50 | H16: 40 | I16: 20 | J16: 65 | K16: 0 | L16: =0.9*SALES!L16 -> 39.6 | M16: =0.92*SALES!M16 -> 37.72 | N16: =0.92*SALES!N16 -> 99.36 | O16: =0.9*SALES!O16 -> 99 | P16: =0.92*SALES!P16 -> 102.12 | Q16: =0.94*SALES!Q16 -> 40.42 | R16: =0.94*SALES!R16 -> 148.52 | S16: =0.9*SALES!S16 -> 391.5 | T16: =0.95*SALES!T16 -> 57 | U16: =0.82*SALES!U16 -> 709.3 | V16: =B16*L16 -> 15840 | W16: =C16*M16 -> 3772 | X16: =D16*N16 -> 4968 | Y16: =E16*O16 -> 4950 | Z16: =F16*P16 -> 5106 | AA16: =G16*Q16 -> 2021 | AB16: =H16*R16 -> 5940.8 | AC16: =I16*S16 -> 7830 | ... AE16: =K16*U16 -> 0 | AF16: =sum(V16:AE16) -> 54132.8
A17: =DATE(2023,4,15) -> 45031 | B17: 0 | C17: 0 | D17: 0 | E17: 0 | F17: 0 | G17: 0 | H17: 0 | I17: 0 | J17: 60 | K17: 0 | L17: =0.9*SALES!L17 -> 39.6 | M17: =0.92*SALES!M17 -> 37.72 | N17: =0.92*SALES!N17 -> 99.36 | O17: =0.9*SALES!O17 -> 99 | P17: =0.92*SALES!P17 -> 102.12 | Q17: =0.94*SALES!Q17 -> 40.42 | R17: =0.94*SALES!R17 -> 148.52 | S17: =0.9*SALES!S17 -> 391.5 | T17: =0.95*SALES!T17 -> 57 | U17: =0.82*SALES!U17 -> 709.3 | V17: =B17*L17 -> 0 | W17: =C17*M17 -> 0 | X17: =D17*N17 -> 0 | Y17: =E17*O17 -> 0 | Z17: =F17*P17 -> 0 | AA17: =G17*Q17 -> 0 | AB17: =H17*R17 -> 0 | AC17: =I17*S17 -> 0 | ... AE17: =K17*U17 -> 0 | AF17: =sum(V17:AE17) -> 3420
A18: =DATE(2023,4,16) -> 45032 | B18: 0 | C18: 0 | D18: 0 | E18: 0 | F18: 0 | G18: 0 | H18: 0 | I18: 0 | J18: 55 | K18: 0 | L18: =0.9*SALES!L18 -> 39.6 | M18: =0.92*SALES!M18 -> 37.72 | N18: =0.92*SALES!N18 -> 99.36 | O18: =0.9*SALES!O18 -> 99 | P18: =0.92*SALES!P18 -> 102.12 | Q18: =0.94*SALES!Q18 -> 40.42 | R18: =0.94*SALES!R18 -> 148.52 | S18: =0.9*SALES!S18 -> 391.5 | T18: =0.95*SALES!T18 -> 57 | U18: =0.82*SALES!U18 -> 709.3 | V18: =B18*L18 -> 0 | W18: =C18*M18 -> 0 | X18: =D18*N18 -> 0 | Y18: =E18*O18 -> 0 | Z18: =F18*P18 -> 0 | AA18: =G18*Q18 -> 0 | AB18: =H18*R18 -> 0 | AC18: =I18*S18 -> 0 | ... AE18: =K18*U18 -> 0 | AF18: =sum(V18:AE18) -> 3135
A19: =DATE(2023,4,17) -> 45033 | B19: 0 | C19: 0 | D19: 0 | E19: 0 | F19: 0 | G19: 0 | H19: 0 | I19: 0 | J19: 55 | K19: 0 | L19: =0.9*SALES!L19 -> 40.5 | M19: =0.92*SALES!M19 -> 37.72 | N19: =0.92*SALES!N19 -> 99.36 | O19: =0.9*SALES!O19 -> 99 | P19: =0.92*SALES!P19 -> 102.12 | Q19: =0.94*SALES!Q19 -> 40.42 | R19: =0.94*SALES!R19 -> 148.52 | S19: =0.9*SALES!S19 -> 391.5 | T19: =0.95*SALES!T19 -> 56.05 | U19: =0.82*SALES!U19 -> 709.3 | V19: =B19*L19 -> 0 | W19: =C19*M19 -> 0 | X19: =D19*N19 -> 0 | Y19: =E19*O19 -> 0 | Z19: =F19*P19 -> 0 | AA19: =G19*Q19 -> 0 | AB19: =H19*R19 -> 0 | AC19: =I19*S19 -> 0 | ... AE19: =K19*U19 -> 0 | AF19: =sum(V19:AE19) -> 3082.75
A20: =DATE(2023,4,18) -> 45034 | B20: 0 | C20: 0 | D20: 0 | E20: 0 | F20: 0 | G20: 0 | H20: 0 | I20: 0 | J20: 55 | K20: 0 | L20: =0.9*SALES!L20 -> 40.5 | M20: =0.92*SALES!M20 -> 37.72 | N20: =0.92*SALES!N20 -> 99.36 | O20: =0.9*SALES!O20 -> 99 | P20: =0.92*SALES!P20 -> 102.12 | Q20: =0.94*SALES!Q20 -> 41.36 | R20: =0.94*SALES!R20 -> 148.52 | S20: =0.9*SALES!S20 -> 391.5 | T20: =0.95*SALES!T20 -> 56.05 | U20: =0.82*SALES!U20 -> 709.3 | V20: =B20*L20 -> 0 | W20: =C20*M20 -> 0 | X20: =D20*N20 -> 0 | Y20: =E20*O20 -> 0 | Z20: =F20*P20 -> 0 | AA20: =G20*Q20 -> 0 | AB20: =H20*R20 -> 0 | AC20: =I20*S20 -> 0 | ... AE20: =K20*U20 -> 0 | AF20: =sum(V20:AE20) -> 3082.75
A21: =DATE(2023,4,19) -> 45035 | B21: 0 | C21: 500 | D21: 0 | E21: 0 | F21: 0 | G21: 120 | H21: 0 | I21: 0 | J21: 55 | K21: 16 | L21: =0.9*SALES!L21 -> 38.7 | M21: =0.92*SALES!M21 -> 37.72 | N21: =0.92*SALES!N21 -> 99.36 | O21: =0.9*SALES!O21 -> 99 | P21: =0.92*SALES!P21 -> 102.12 | Q21: =0.94*SALES!Q21 -> 44.18 | R21: =0.94*SALES!R21 -> 148.52 | S21: =0.9*SALES!S21 -> 391.5 | T21: =0.95*SALES!T21 -> 56.05 | U21: =0.82*SALES!U21 -> 729.8 | V21: =B21*L21 -> 0 | W21: =C21*M21 -> 18860 | X21: =D21*N21 -> 0 | Y21: =E21*O21 -> 0 | Z21: =F21*P21 -> 0 | AA21: =G21*Q21 -> 5301.6 | AB21: =H21*R21 -> 0 | AC21: =I21*S21 -> 0 | ... AE21: =K21*U21 -> 11676.8 | AF21: =sum(V21:AE21) -> 38921.15
A22: =DATE(2023,4,20) -> 45036 | B22: 900 | C22: 0 | D22: 140 | E22: 60 | F22: 100 | G22: 160 | H22: 0 | I22: 0 | J22: 55 | K22: 0 | L22: =0.9*SALES!L22 -> 40.5 | M22: =0.92*SALES!M22 -> 37.72 | N22: =0.92*SALES!N22 -> 95.68 | O22: =0.9*SALES!O22 -> 101.7 | P22: =0.92*SALES!P22 -> 112.24 | Q22: =0.94*SALES!Q22 -> 42.3 | R22: =0.94*SALES!R22 -> 148.52 | S22: =0.9*SALES!S22 -> 391.5 | T22: =0.95*SALES!T22 -> 56.05 | U22: =0.82*SALES!U22 -> 729.8 | V22: =B22*L22 -> 36450 | W22: =C22*M22 -> 0 | X22: =D22*N22 -> 13395.2 | Y22: =E22*O22 -> 6102 | Z22: =F22*P22 -> 11224 | AA22: =G22*Q22 -> 6768 | AB22: =H22*R22 -> 0 | AC22: =I22*S22 -> 0 | ... AE22: =K22*U22 -> 0 | AF22: =sum(V22:AE22) -> 77021.95
A23: =DATE(2023,4,21) -> 45037 | B23: 0 | C23: 0 | D23: 0 | E23: 0 | F23: 0 | G23: 0 | H23: 180 | I23: 100 | J23: 50 | K23: 10 | L23: =0.9*SALES!L23 -> 40.5 | M23: =0.92*SALES!M23 -> 37.72 | N23: =0.92*SALES!N23 -> 95.68 | O23: =0.9*SALES!O23 -> 101.7 | P23: =0.92*SALES!P23 -> 112.24 | Q23: =0.94*SALES!Q23 -> 42.3 | R23: =0.94*SALES!R23 -> 133.48 | S23: =0.9*SALES!S23 -> 396 | T23: =0.95*SALES!T23 -> 57 | U23: =0.82*SALES!U23 -> 733.9 | V23: =B23*L23 -> 0 | W23: =C23*M23 -> 0 | X23: =D23*N23 -> 0 | Y23: =E23*O23 -> 0 | Z23: =F23*P23 -> 0 | AA23: =G23*Q23 -> 0 | AB23: =H23*R23 -> 24026.4 | AC23: =I23*S23 -> 39600 | ... AE23: =K23*U23 -> 7339 | AF23: =sum(V23:AE23) -> 73815.4
A24: =DATE(2023,4,22) -> 45038 | B24: 0 | C24: 0 | D24: 0 | E24: 0 | F24: 0 | G24: 0 | H24: 0 | I24: 0 | J24: 90 | K24: 0 | L24: =0.9*SALES!L24 -> 40.5 | M24: =0.92*SALES!M24 -> 37.72 | N24: =0.92*SALES!N24 -> 95.68 | O24: =0.9*SALES!O24 -> 101.7 | P24: =0.92*SALES!P24 -> 112.24 | Q24: =0.94*SALES!Q24 -> 42.3 | R24: =0.94*SALES!R24 -> 133.48 | S24: =0.9*SALES!S24 -> 396 | T24: =0.95*SALES!T24 -> 57 | U24: =0.82*SALES!U24 -> 733.9 | V24: =B24*L24 -> 0 | W24: =C24*M24 -> 0 | X24: =D24*N24 -> 0 | Y24: =E24*O24 -> 0 | Z24: =F24*P24 -> 0 | AA24: =G24*Q24 -> 0 | AB24: =H24*R24 -> 0 | AC24: =I24*S24 -> 0 | ... AE24: =K24*U24 -> 0 | AF24: =sum(V24:AE24) -> 5130
A25: =DATE(2023,4,23) -> 45039 | B25: 0 | C25: 0 | D25: 0 | E25: 0 | F25: 0 | G25: 0 | H25: 0 | I25: 0 | J25: 90 | K25: 0 | L25: =0.9*SALES!L25 -> 40.5 | M25: =0.92*SALES!M25 -> 37.72 | N25: =0.92*SALES!N25 -> 95.68 | O25: =0.9*SALES!O25 -> 101.7 | P25: =0.92*SALES!P25 -> 112.24 | Q25: =0.94*SALES!Q25 -> 42.3 | R25: =0.94*SALES!R25 -> 122.2 | S25: =0.9*SALES!S25 -> 396 | T25: =0.95*SALES!T25 -> 57 | U25: =0.82*SALES!U25 -> 733.9 | V25: =B25*L25 -> 0 | W25: =C25*M25 -> 0 | X25: =D25*N25 -> 0 | Y25: =E25*O25 -> 0 | Z25: =F25*P25 -> 0 | AA25: =G25*Q25 -> 0 | AB25: =H25*R25 -> 0 | AC25: =I25*S25 -> 0 | ... AE25: =K25*U25 -> 0 | AF25: =sum(V25:AE25) -> 5130
A26: =DATE(2023,4,24) -> 45040 | B26: 500 | C26: 0 | D26: 50 | E26: 50 | F26: 50 | G26: 100 | H26: 60 | I26: 0 | J26: 100 | K26: 20 | L26: =0.9*SALES!L26 -> 40.5 | M26: =0.92*SALES!M26 -> 37.72 | N26: =0.92*SALES!N26 -> 95.68 | O26: =0.9*SALES!O26 -> 101.7 | P26: =0.92*SALES!P26 -> 112.24 | Q26: =0.94*SALES!Q26 -> 42.3 | R26: =0.94*SALES!R26 -> 122.2 | S26: =0.9*SALES!S26 -> 396 | T26: =0.95*SALES!T26 -> 57 | U26: =0.82*SALES!U26 -> 733.9 | V26: =B26*L26 -> 20250 | W26: =C26*M26 -> 0 | X26: =D26*N26 -> 4784 | Y26: =E26*O26 -> 5085 | Z26: =F26*P26 -> 5612 | AA26: =G26*Q26 -> 4230 | AB26: =H26*R26 -> 7332 | AC26: =I26*S26 -> 0 | ... AE26: =K26*U26 -> 14678 | AF26: =sum(V26:AE26) -> 67671
A27: =DATE(2023,4,25) -> 45041 | B27: 0 | C27: 0 | D27: 0 | E27: 0 | F27: 0 | G27: 0 | H27: 0 | I27: 0 | J27: 100 | K27: 0 | L27: =0.9*SALES!L27 -> 40.5 | M27: =0.92*SALES!M27 -> 37.72 | N27: =0.92*SALES!N27 -> 95.68 | O27: =0.9*SALES!O27 -> 101.7 | P27: =0.92*SALES!P27 -> 112.24 | Q27: =0.94*SALES!Q27 -> 42.3 | R27: =0.94*SALES!R27 -> 122.2 | S27: =0.9*SALES!S27 -> 396 | T27: =0.95*SALES!T27 -> 57 | U27: =0.82*SALES!U27 -> 733.9 | V27: =B27*L27 -> 0 | W27: =C27*M27 -> 0 | X27: =D27*N27 -> 0 | Y27: =E27*O27 -> 0 | Z27: =F27*P27 -> 0 | AA27: =G27*Q27 -> 0 | AB27: =H27*R27 -> 0 | AC27: =I27*S27 -> 0 | ... AE27: =K27*U27 -> 0 | AF27: =sum(V27:AE27) -> 5700
A28: =DATE(2023,4,26) -> 45042 | B28: 0 | C28: 0 | D28: 0 | E28: 0 | F28: 0 | G28: 0 | H28: 0 | I28: 0 | J28: 60 | K28: 0 | L28: =0.9*SALES!L28 -> 40.5 | M28: =0.92*SALES!M28 -> 37.72 | N28: =0.92*SALES!N28 -> 95.68 | O28: =0.9*SALES!O28 -> 101.7 | P28: =0.92*SALES!P28 -> 112.24 | Q28: =0.94*SALES!Q28 -> 42.3 | R28: =0.94*SALES!R28 -> 122.2 | S28: =0.9*SALES!S28 -> 396 | T28: =0.95*SALES!T28 -> 57 | U28: =0.82*SALES!U28 -> 733.9 | V28: =B28*L28 -> 0 | W28: =C28*M28 -> 0 | X28: =D28*N28 -> 0 | Y28: =E28*O28 -> 0 | Z28: =F28*P28 -> 0 | AA28: =G28*Q28 -> 0 | AB28: =H28*R28 -> 0 | AC28: =I28*S28 -> 0 | ... AE28: =K28*U28 -> 0 | AF28: =sum(V28:AE28) -> 3420
A29: =DATE(2023,4,27) -> 45043 | B29: 600 | C29: 160 | D29: 0 | E29: 0 | F29: 0 | G29: 0 | H29: 60 | I29: 0 | J29: 55 | K29: 0 | L29: =0.9*SALES!L29 -> 40.5 | M29: =0.92*SALES!M29 -> 37.72 | N29: =0.92*SALES!N29 -> 95.68 | O29: =0.9*SALES!O29 -> 101.7 | P29: =0.92*SALES!P29 -> 112.24 | Q29: =0.94*SALES!Q29 -> 42.3 | R29: =0.94*SALES!R29 -> 122.2 | S29: =0.9*SALES!S29 -> 396 | T29: =0.95*SALES!T29 -> 57 | U29: =0.82*SALES!U29 -> 733.9 | V29: =B29*L29 -> 24300 | W29: =C29*M29 -> 6035.2 | X29: =D29*N29 -> 0 | Y29: =E29*O29 -> 0 | Z29: =F29*P29 -> 0 | AA29: =G29*Q29 -> 0 | AB29: =H29*R29 -> 7332 | AC29: =I29*S29 -> 0 | ... AE29: =K29*U29 -> 0 | AF29: =sum(V29:AE29) -> 40802.2
A30: =DATE(2023,4,28) -> 45044 | B30: 0 | C30: 0 | D30: 50 | E30: 40 | F30: 60 | G30: 0 | H30: 0 | I30: 0 | J30: 65 | K30: 8 | L30: =0.9*SALES!L30 -> 40.5 | M30: =0.92*SALES!M30 -> 37.72 | N30: =0.92*SALES!N30 -> 95.68 | O30: =0.9*SALES!O30 -> 101.7 | P30: =0.92*SALES!P30 -> 112.24 | Q30: =0.94*SALES!Q30 -> 42.3 | R30: =0.94*SALES!R30 -> 122.2 | S30: =0.9*SALES!S30 -> 396 | T30: =0.95*SALES!T30 -> 57 | U30: =0.82*SALES!U30 -> 721.6 | V30: =B30*L30 -> 0 | W30: =C30*M30 -> 0 | X30: =D30*N30 -> 4784 | Y30: =E30*O30 -> 4068 | Z30: =F30*P30 -> 6734.4 | AA30: =G30*Q30 -> 0 | AB30: =H30*R30 -> 0 | AC30: =I30*S30 -> 0 | ... AE30: =K30*U30 -> 5772.8 | AF30: =sum(V30:AE30) -> 25064.2
A31: =DATE(2023,4,29) -> 45045 | B31: 0 | C31: 0 | D31: 0 | E31: 0 | F31: 0 | G31: 0 | H31: 0 | I31: 0 | J31: 55 | K31: 0 | L31: =0.9*SALES!L31 -> 42.3 | M31: =0.92*SALES!M31 -> 37.72 | N31: =0.92*SALES!N31 -> 95.68 | O31: =0.9*SALES!O31 -> 101.7 | P31: =0.92*SALES!P31 -> 112.24 | Q31: =0.94*SALES!Q31 -> 42.3 | R31: =0.94*SALES!R31 -> 122.2 | S31: =0.9*SALES!S31 -> 396 | T31: =0.95*SALES!T31 -> 57 | U31: =0.82*SALES!U31 -> 721.6 | V31: =B31*L31 -> 0 | W31: =C31*M31 -> 0 | X31: =D31*N31 -> 0 | Y31: =E31*O31 -> 0 | Z31: =F31*P31 -> 0 | AA31: =G31*Q31 -> 0 | AB31: =H31*R31 -> 0 | AC31: =I31*S31 -> 0 | ... AE31: =K31*U31 -> 0 | AF31: =sum(V31:AE31) -> 3135
A32: =DATE(2023,4,30) -> 45046 | B32: 0 | C32: 0 | D32: 0 | E32: 0 | F32: 0 | G32: 0 | H32: 0 | I32: 0 | J32: 55 | K32: 0 | L32: =0.9*SALES!L32 -> 42.3 | M32: =0.92*SALES!M32 -> 37.72 | N32: =0.92*SALES!N32 -> 95.68 | O32: =0.9*SALES!O32 -> 101.7 | P32: =0.92*SALES!P32 -> 112.24 | Q32: =0.94*SALES!Q32 -> 42.3 | R32: =0.94*SALES!R32 -> 132.54 | S32: =0.9*SALES!S32 -> 396 | T32: =0.95*SALES!T32 -> 57 | U32: =0.82*SALES!U32 -> 721.6 | V32: =B32*L32 -> 0 | W32: =C32*M32 -> 0 | X32: =D32*N32 -> 0 | Y32: =E32*O32 -> 0 | Z32: =F32*P32 -> 0 | AA32: =G32*Q32 -> 0 | AB32: =H32*R32 -> 0 | AC32: =I32*S32 -> 0 | ... AE32: =K32*U32 -> 0 | AF32: =sum(V32:AE32) -> 3135
A33: =DATE(2023,4,31) -> 45047 | B33: 0 | C33: 0 | D33: 0 | E33: 0 | F33: 0 | G33: 0 | H33: 0 | I33: 0 | J33: 55 | K33: 0 | L33: =0.9*SALES!L33 -> 42.3 | M33: =0.92*SALES!M33 -> 37.72 | N33: =0.92*SALES!N33 -> 96.6 | O33: =0.9*SALES!O33 -> 101.7 | P33: =0.92*SALES!P33 -> 108.56 | Q33: =0.94*SALES!Q33 -> 42.3 | R33: =0.94*SALES!R33 -> 132.54 | S33: =0.9*SALES!S33 -> 396 | T33: =0.95*SALES!T33 -> 57 | U33: =0.82*SALES!U33 -> 721.6 | V33: =B33*L33 -> 0 | W33: =C33*M33 -> 0 | X33: =D33*N33 -> 0 | Y33: =E33*O33 -> 0 | Z33: =F33*P33 -> 0 | AA33: =G33*Q33 -> 0 | AB33: =H33*R33 -> 0 | AC33: =I33*S33 -> 0 | ... AE33: =K33*U33 -> 0 | AF33: =sum(V33:AE33) -> 3135
B34: =SUM(B3:B33) -> 2400 | C34: =SUM(C3:C33) -> 1160 | D34: =SUM(D3:D33) -> 390 | E34: =SUM(E3:E33) -> 300 | F34: =SUM(F3:F33) -> 410 | G34: =SUM(G3:G33) -> 480 | H34: =SUM(H3:H33) -> 480 | I34: =SUM(I3:I33) -> 155 | J34: =SUM(J3:J33) -> 2005 | K34: AVG PRICE--> | L34: =SUM(L3:L33)/31 -> 40.122581 | M34: =SUM(M3:M33)/31 -> 37.898065 | N34: =SUM(N3:N33)/31 -> 96.065806 | O34: =SUM(O3:O33)/31 -> 100.04516 | P34: =SUM(P3:P33)/31 -> 105.94839 | Q34: =SUM(Q3:Q33)/31 -> 41.48129 | R34: =SUM(R3:R33)/31 -> 142.33419 | S34: =SUM(S3:S33)/31 -> 391.67419 | ... U34: =SUM(U3:U33)/31 -> 716.97097 | V34: =sum(V3:V33) -> 96840 | W34: =sum(W3:W33) -> 43755.2 | X34: =sum(X3:X33) -> 37315.2 | Y34: =sum(Y3:Y33) -> 30105 | Z34: =sum(Z3:Z33) -> 44132.4 | AA34: =sum(AA3:AA33) -> 20341.6 | AB34: =sum(AB3:AB33) -> 66288.8 | AC34: =sum(AC3:AC33) -> 60862.5 | ... AE34: =sum(AE3:AE33) -> 70315 | AF34: =SUM(AF3:AF33) -> 584031.7
K35: TOTAL AVG= | L35: =SUM(L34:U34)/10 -> 172.94181 | U35: Initial Inventory | V35: =(INVENTORY!B3*L3) -> 36450 | W35: =(INVENTORY!C3*M3) -> 7544 | X35: =(INVENTORY!D3*N3) -> 7507.2 | Y35: =(INVENTORY!E3*O3) -> 4950 | Z35: =(INVENTORY!F3*P3) -> 14425.6 | AA35: =(INVENTORY!G3*Q3) -> 11844 | AB35: =(INVENTORY!H3*R3) -> 20163 | AC35: =(INVENTORY!I3*S3) -> 18720 | ... AE35: =(INVENTORY!K3*U3) -> 4206.6
U36: End Inventory | V36: =INVENTORY!B33*L33 -> 13282.2 | W36: =INVENTORY!C33*M33 -> 3922.88 | X36: =INVENTORY!D33*N33 -> 3670.8 | Y36: =INVENTORY!E33*O33 -> 3254.4 | Z36: =INVENTORY!F33*P33 -> 5645.12 | AA36: =INVENTORY!G33*Q33 -> 2030.4 | AB36: =INVENTORY!H33*R33 -> 7687.32 | AC36: =INVENTORY!I33*S33 -> 6336 | ... AE36: =INVENTORY!K33*U33 -> 5772.8
U37: Final Expenditure | V37: =V34+V35-V36 -> 120007.8 | W37: =W34+W35-W36 -> 47376.32 | X37: =X34+X35-X36 -> 41151.6 | Y37: =Y34+Y35-Y36 -> 31800.6 | Z37: =Z34+Z35-Z36 -> 52912.88 | AA37: =AA34+AA35-AA36 -> 30155.2 | AB37: =AB34+AB35-AB36 -> 78764.48 | AC37: =AC34+AC35-AC36 -> 73246.5 | ... AE37: =AE34+AE35-AE36 -> 68748.8 | AF37: =sum(V37:AE37) -> 658240.18
A40: DATE | B40: COOKING OIL | C40: CP | E40: DATE | F40: URAD DAL | G40: URAD DAL
A41: =DATE(2023,4,1) -> 45017 | B41: 0 | C41: 155.1 | E41: =DATE(2023,4,1) -> 45017 | F41: 0 | G41: 103.04
A42: =DATE(2023,4,2) -> 45018 | B42: 0 | C42: 155.1 | E42: =DATE(2023,4,2) -> 45018 | F42: 0 | G42: 103.04
...

Sheet INVENTORY
F1: INVENTORY
A2: DATE | B2: RICE | C2: ATTA | D2: TOOR DAL | E2: MOONG DAL | F2: URAD DAL | G2: SUGAR | H2: COOKING OIL | I2: GHEE | J2: MILK & DAIRY | K2: DRY FRUITS | L2: TOTAL DAILY INVENTORY | M2: AVERAGE DAILY TOTAL INVENTORY | N2: DATE
A3: =DATE(2023,4,1) -> 45017 | B3: 900 | C3: 200 | D3: 80 | E3: 50 | F3: 140 | G3: 280 | H3: 130 | I3: 50 | J3: 0 | K3: 6 | L3: =SUM(B3:K3) -> 1836 | M3: =L3/10 -> 183.6 | N3: =DATE(2023,4,1) -> 45017
A4: =DATE(2023,4,2) -> 45018 | B4: =B3-SALES!B3+PURCHASE!B3 -> 760 | C4: =C3-SALES!C3+PURCHASE!C3 -> 90 | D4: =D3-SALES!D3+PURCHASE!D3 -> 56 | E4: =E3-SALES!E3+PURCHASE!E3 -> 34 | F4: =F3-SALES!F3+PURCHASE!F3 -> 100 | G4: =G3-SALES!G3+PURCHASE!G3 -> 210 | H4: =H3-SALES!H3+PURCHASE!H3 -> 94 | I4: =I3-SALES!I3+PURCHASE!I3 -> 30 | J4: 0 | K4: =K3-SALES!K3+PURCHASE!K3 -> 40 | L4: =SUM(B4:K4) -> 1414 | M4: =L4/10 -> 141.4 | N4: =DATE(2023,4,2) -> 45018
A5: =DATE(2023,4,3) -> 45019 | B5: =B4-SALES!B4+PURCHASE!B4 -> 670 | C5: =C4-SALES!C4+PURCHASE!C4 -> 210 | D5: =D4-SALES!D4+PURCHASE!D4 -> 28 | E5: =E4-SALES!E4+PURCHASE!E4 -> 70 | F5: =F4-SALES!F4+PURCHASE!F4 -> 56 | G5: =G4-SALES!G4+PURCHASE!G4 -> 162 | H5: =H4-SALES!H4+PURCHASE!H4 -> 64 | I5: =I4-SALES!I4+PURCHASE!I4 -> 20 | J5: 0 | K5: =K4-SALES!K4+PURCHASE!K4 -> 34 | L5: =SUM(B5:K5) -> 1314 | M5: =L5/10 -> 131.4 | N5: =DATE(2023,4,3) -> 45019
A6: =DATE(2023,4,4) -> 45020 | B6: =B5-SALES!B5+PURCHASE!B5 -> 600 | C6: =C5-SALES!C5+PURCHASE!C5 -> 160 | D6: =D5-SALES!D5+PURCHASE!D5 -> 58 | E6: =E5-SALES!E5+PURCHASE!E5 -> 50 | F6: =F5-SALES!F5+PURCHASE!F5 -> 56 | G6: =G5-SALES!G5+PURCHASE!G5 -> 122 | H6: =H5-SALES!H5+PURCHASE!H5 -> 84 | I6: =I5-SALES!I5+PURCHASE!I5 -> 32 | J6: 0 | K6: =K5-SALES!K5+PURCHASE!K5 -> 30 | L6: =SUM(B6:K6) -> 1192 | M6: =L6/10 -> 119.2 | N6: =DATE(2023,4,4) -> 45020
A7: =DATE(2023,4,5) -> 45021 | B7: =B6-SALES!B6+PURCHASE!B6 -> 540 | C7: =C6-SALES!C6+PURCHASE!C6 -> 120 | D7: =D6-SALES!D6+PURCHASE!D6 -> 36 | E7: =E6-SALES!E6+PURCHASE!E6 -> 34 | F7: =F6-SALES!F6+PURCHASE!F6 -> 62 | G7: =G6-SALES!G6+PURCHASE!G6 -> 80 | H7: =H6-SALES!H6+PURCHASE!H6 -> 104 | I7: =I6-SALES!I6+PURCHASE!I6 -> 22 | J7: 0 | K7: =K6-SALES!K6+PURCHASE!K6 -> 24 | L7: =SUM(B7:K7) -> 1022 | M7: =L7/10 -> 102.2 | N7: =DATE(2023,4,5) -> 45021
A8: =DATE(2023,4,6) -> 45022 | B8: =B7-SALES!B7+PURCHASE!B7 -> 474 | C8: =C7-SALES!C7+PURCHASE!C7 -> 84 | D8: =D7-SALES!D7+PURCHASE!D7 -> 18 | E8: =E7-SALES!E7+PURCHASE!E7 -> 20 | F8: =F7-SALES!F7+PURCHASE!F7 -> 22 | G8: =G7-SALES!G7+PURCHASE!G7 -> 32 | H8: =H7-SALES!H7+PURCHASE!H7 -> 66 | I8: =I7-SALES!I7+PURCHASE!I7 -> 11 | J8: 0 | K8: =K7-SALES!K7+PURCHASE!K7 -> 14 | L8: =SUM(B8:K8) -> 741 | M8: =L8/10 -> 74.1 | N8: =DATE(2023,4,6) -> 45022
A9: =DATE(2023,4,7) -> 45023 | B9: =B8-SALES!B8+PURCHASE!B8 -> 454 | C9: =C8-SALES!C8+PURCHASE!C8 -> 260 | D9: =D8-SALES!D8+PURCHASE!D8 -> 60 | E9: =E8-SALES!E8+PURCHASE!E8 -> 12 | F9: =F8-SALES!F8+PURCHASE!F8 -> 68 | G9: =G8-SALES!G8+PURCHASE!G8 -> 72 | H9: =H8-SALES!H8+PURCHASE!H8 -> 58 | I9: =I8-SALES!I8+PURCHASE!I8 -> 7 | J9: 0 | K9: =K8-SALES!K8+PURCHASE!K8 -> 14 | L9: =SUM(B9:K9) -> 1005 | M9: =L9/10 -> 100.5 | N9: =DATE(2023,4,7) -> 45023
A10: =DATE(2023,4,8) -> 45024 | B10: =B9-SALES!B9+PURCHASE!B9 -> 414 | C10: =C9-SALES!C9+PURCHASE!C9 -> 240 | D10: =D9-SALES!D9+PURCHASE!D9 -> 52 | E10: =E9-SALES!E9+PURCHASE!E9 -> 56 | F10: =F9-SALES!F9+PURCHASE!F9 -> 60 | G10: =G9-SALES!G9+PURCHASE!G9 -> 64 | H10: =H9-SALES!H9+PURCHASE!H9 -> 52 | I10: =I9-SALES!I9+PURCHASE!I9 -> 20 | J10: 0 | K10: =K9-SALES!K9+PURCHASE!K9 -> 12 | L10: =SUM(B10:K10) -> 970 | M10: =L10/10 -> 97 | N10: =DATE(2023,4,8) -> 45024
A11: =DATE(2023,4,9) -> 45025 | B11: =B10-SALES!B10+PURCHASE!B10 -> 374 | C11: =C10-SALES!C10+PURCHASE!C10 -> 216 | D11: =D10-SALES!D10+PURCHASE!D10 -> 44 | E11: =E10-SALES!E10+PURCHASE!E10 -> 50 | F11: =F10-SALES!F10+PURCHASE!F10 -> 54 | G11: =G10-SALES!G10+PURCHASE!G10 -> 54 | H11: =H10-SALES!H10+PURCHASE!H10 -> 44 | I11: =I10-SALES!I10+PURCHASE!I10 -> 16 | J11: 0 | K11: =K10-SALES!K10+PURCHASE!K10 -> 8 | L11: =SUM(B11:K11) -> 860 | M11: =L11/10 -> 86 | N11: =DATE(2023,4,9) -> 45025
A12: =DATE(2023,4,10) -> 45026 | B12: =B11-SALES!B11+PURCHASE!B11 -> 314 | C12: =C11-SALES!C11+PURCHASE!C11 -> 186 | D12: =D11-SALES!D11+PURCHASE!D11 -> 38 | E12: =E11-SALES!E11+PURCHASE!E11 -> 46 | F12: =F11-SALES!F11+PURCHASE!F11 -> 50 | G12: =G11-SALES!G11+PURCHASE!G11 -> 48 | H12: =H11-SALES!H11+PURCHASE!H11 -> 58 | I12: =I11-SALES!I11+PURCHASE!I11 -> 12 | J12: 0 | K12: =K11-SALES!K11+PURCHASE!K11 -> 4 | L12: =SUM(B12:K12) -> 756 | M12: =L12/10 -> 75.6 | N12: =DATE(2023,4,10) -> 45026
A13: =DATE(2023,4,11) -> 45027 | B13: =B12-SALES!B12+PURCHASE!B12 -> 258 | C13: =C12-SALES!C12+PURCHASE!C12 -> 154 | D13: =D12-SALES!D12+PURCHASE!D12 -> 30 | E13: =E12-SALES!E12+PURCHASE!E12 -> 40 | F13: =F12-SALES!F12+PURCHASE!F12 -> 46 | G13: =G12-SALES!G12+PURCHASE!G12 -> 40 | H13: =H12-SALES!H12+PURCHASE!H12 -> 50 | I13: =I12-SALES!I12+PURCHASE!I12 -> 12 | J13: 0 | K13: =K12-SALES!K12+PURCHASE!K12 -> 4 | L13: =SUM(B13:K13) -> 634 | M13: =L13/10 -> 63.4 | N13: =DATE(2023,4,11) -> 45027
A14: =DATE(2023,4,12) -> 45028 | B14: =B13-SALES!B13+PURCHASE!B13 -> 210 | C14: =C13-SALES!C13+PURCHASE!C13 -> 130 | D14: =D13-SALES!D13+PURCHASE!D13 -> 24 | E14: =E13-SALES!E13+PURCHASE!E13 -> 32 | F14: =F13-SALES!F13+PURCHASE!F13 -> 40 | G14: =G13-SALES!G13+PURCHASE!G13 -> 32 | H14: =H13-SALES!H13+PURCHASE!H13 -> 44 | I14: =I13-SALES!I13+PURCHASE!I13 -> 10 | J14: 0 | K14: =K13-SALES!K13+PURCHASE!K13 -> 4 | L14: =SUM(B14:K14) -> 526 | M14: =L14/10 -> 52.6 | N14: =DATE(2023,4,12) -> 45028
A15: =DATE(2023,4,13) -> 45029 | B15: =B14-SALES!B14+PURCHASE!B14 -> 162 | C15: =C14-SALES!C14+PURCHASE!C14 -> 102 | D15: =D14-SALES!D14+PURCHASE!D14 -> 16 | E15: =E14-SALES!E14+PURCHASE!E14 -> 24 | F15: =F14-SALES!F14+PURCHASE!F14 -> 32 | G15: =G14-SALES!G14+PURCHASE!G14 -> 26 | H15: =H14-SALES!H14+PURCHASE!H14 -> 38 | I15: =I14-SALES!I14+PURCHASE!I14 -> 8 | J15: 0 | K15: =K14-SALES!K14+PURCHASE!K14 -> 4 | L15: =SUM(B15:K15) -> 412 | M15: =L15/10 -> 41.2 | N15: =DATE(2023,4,13) -> 45029
A16: =DATE(2023,4,14) -> 45030 | B16: =B15-SALES!B15+PURCHASE!B15 -> 112 | C16: =C15-SALES!C15+PURCHASE!C15 -> 74 | D16: =D15-SALES!D15+PURCHASE!D15 -> 10 | E16: =E15-SALES!E15+PURCHASE!E15 -> 16 | F16: =F15-SALES!F15+PURCHASE!F15 -> 26 | G16: =G15-SALES!G15+PURCHASE!G15 -> 16 | H16: =H15-SALES!H15+PURCHASE!H15 -> 34 | I16: =I15-SALES!I15+PURCHASE!I15 -> 8 | J16: 0 | K16: =K15-SALES!K15+PURCHASE!K15 -> 4 | L16: =SUM(B16:K16) -> 300 | M16: =L16/10 -> 30 | N16: =DATE(2023,4,14) -> 45030
A17: =DATE(2023,4,15) -> 45031 | B17: =B16-SALES!B16+PURCHASE!B16 -> 406 | C17: =C16-SALES!C16+PURCHASE!C16 -> 140 | D17: =D16-SALES!D16+PURCHASE!D16 -> 48 | E17: =E16-SALES!E16+PURCHASE!E16 -> 58 | F17: =F16-SALES!F16+PURCHASE!F16 -> 66 | G17: =G16-SALES!G16+PURCHASE!G16 -> 54 | H17: =H16-SALES!H16+PURCHASE!H16 -> 66 | I17: =I16-SALES!I16+PURCHASE!I16 -> 26 | J17: 0 | K17: =K16-SALES!K16+PURCHASE!K16 -> 4 | L17: =SUM(B17:K17) -> 868 | M17: =L17/10 -> 86.8 | N17: =DATE(2023,4,15) -> 45031
A18: =DATE(2023,4,16) -> 45032 | B18: =B17-SALES!B17+PURCHASE!B17 -> 364 | C18: =C17-SALES!C17+PURCHASE!C17 -> 116 | D18: =D17-SALES!D17+PURCHASE!D17 -> 42 | E18: =E17-SALES!E17+PURCHASE!E17 -> 48 | F18: =F17-SALES!F17+PURCHASE!F17 -> 58 | G18: =G17-SALES!G17+PURCHASE!G17 -> 50 | H18: =H17-SALES!H17+PURCHASE!H17 -> 62 | I18: =I17-SALES!I17+PURCHASE!I17 -> 26 | J18: 0 | K18: =K17-SALES!K17+PURCHASE!K17 -> 4 | L18: =SUM(B18:K18) -> 770 | M18: =L18/10 -> 77 | N18: =DATE(2023,4,16) -> 45032
A19: =DATE(2023,4,17) -> 45033 | B19: =B18-SALES!B18+PURCHASE!B18 -> 324 | C19: =C18-SALES!C18+PURCHASE!C18 -> 90 | D19: =D18-SALES!D18+PURCHASE!D18 -> 32 | E19: =E18-SALES!E18+PURCHASE!E18 -> 38 | F19: =F18-SALES!F18+PURCHASE!F18 -> 48 | G19: =G18-SALES!G18+PURCHASE!G18 -> 46 | H19: =H18-SALES!H18+PURCHASE!H18 -> 56 | I19: =I18-SALES!I18+PURCHASE!I18 -> 26 | J19: 0 | K19: =K18-SALES!K18+PURCHASE!K18 -> 3 | L19: =SUM(B19:K19) -> 663 | M19: =L19/10 -> 66.3 | N19: =DATE(2023,4,17) -> 45033
A20: =DATE(2023,4,18) -> 45034 | B20: =B19-SALES!B19+PURCHASE!B19 -> 272 | C20: =C19-SALES!C19+PURCHASE!C19 -> 70 | D20: =D19-SALES!D19+PURCHASE!D19 -> 28 | E20: =E19-SALES!E19+PURCHASE!E19 -> 36 | F20: =F19-SALES!F19+PURCHASE!F19 -> 42 | G20: =G19-SALES!G19+PURCHASE!G19 -> 42 | H20: =H19-SALES!H19+PURCHASE!H19 -> 54 | I20: =I19-SALES!I19+PURCHASE!I19 -> 26 | J20: 0 | K20: =K19-SALES!K19+PURCHASE!K19 -> 3 | L20: =SUM(B20:K20) -> 573 | M20: =L20/10 -> 57.3 | N20: =DATE(2023,4,18) -> 45034
A21: =DATE(2023,4,19) -> 45035 | B21: =B20-SALES!B20+PURCHASE!B20 -> 232 | C21: =C20-SALES!C20+PURCHASE!C20 -> 40 | D21: =D20-SALES!D20+PURCHASE!D20 -> 24 | E21: =E20-SALES!E20+PURCHASE!E20 -> 34 | F21: =F20-SALES!F20+PURCHASE!F20 -> 40 | G21: =G20-SALES!G20+PURCHASE!G20 -> 40 | H21: =H20-SALES!H20+PURCHASE!H20 -> 54 | I21: =I20-SALES!I20+PURCHASE!I20 -> 24 | J21: 0 | K21: =K20-SALES!K20+PURCHASE!K20 -> 3 | L21: =SUM(B21:K21) -> 491 | M21: =L21/10 -> 49.1 | N21: =DATE(2023,4,19) -> 45035
A22: =DATE(2023,4,20) -> 45036 | B22: =B21-SALES!B21+PURCHASE!B21 -> 196 | C22: =C21-SALES!C21+PURCHASE!C21 -> 520 | D22: =D21-SALES!D21+PURCHASE!D21 -> 18 | E22: =E21-SALES!E21+PURCHASE!E21 -> 32 | F22: =F21-SALES!F21+PURCHASE!F21 -> 34 | G22: =G21-SALES!G21+PURCHASE!G21 -> 156 | H22: =H21-SALES!H21+PURCHASE!H21 -> 50 | I22: =I21-SALES!I21+PURCHASE!I21 -> 22 | J22: 0 | K22: =K21-SALES!K21+PURCHASE!K21 -> 19 | L22: =SUM(B22:K22) -> 1047 | M22: =L22/10 -> 104.7 | N22: =DATE(2023,4,20) -> 45036
A23: =DATE(2023,4,21) -> 45037 | B23: =B22-SALES!B22+PURCHASE!B22 -> 1058 | C23: =C22-SALES!C22+PURCHASE!C22 -> 502 | D23: =D22-SALES!D22+PURCHASE!D22 -> 154 | E23: =E22-SALES!E22+PURCHASE!E22 -> 86 | F23: =F22-SALES!F22+PURCHASE!F22 -> 126 | G23: =G22-SALES!G22+PURCHASE!G22 -> 310 | H23: =H22-SALES!H22+PURCHASE!H22 -> 46 | I23: =I22-SALES!I22+PURCHASE!I22 -> 20 | J23: 0 | K23: =K22-SALES!K22+PURCHASE!K22 -> 17 | L23: =SUM(B23:K23) -> 2319 | M23: =L23/10 -> 231.9 | N23: =DATE(2023,4,21) -> 45037
A24: =DATE(2023,4,22) -> 45038 | B24: =B23-SALES!B23+PURCHASE!B23 -> 1010 | C24: =C23-SALES!C23+PURCHASE!C23 -> 472 | D24: =D23-SALES!D23+PURCHASE!D23 -> 146 | E24: =E23-SALES!E23+PURCHASE!E23 -> 84 | F24: =F23-SALES!F23+PURCHASE!F23 -> 124 | G24: =G23-SALES!G23+PURCHASE!G23 -> 302 | H24: =H23-SALES!H23+PURCHASE!H23 -> 220 | I24: =I23-SALES!I23+PURCHASE!I23 -> 116 | J24: 0 | K24: =K23-SALES!K23+PURCHASE!K23 -> 25 | L24: =SUM(B24:K24) -> 2499 | M24: =L24/10 -> 249.9 | N24: =DATE(2023,4,22) -> 45038
A25: =DATE(2023,4,23) -> 45039 | B25: =B24-SALES!B24+PURCHASE!B24 -> 750 | C25: =C24-SALES!C24+PURCHASE!C24 -> 382 | D25: =D24-SALES!D24+PURCHASE!D24 -> 110 | E25: =E24-SALES!E24+PURCHASE!E24 -> 58 | F25: =F24-SALES!F24+PURCHASE!F24 -> 96 | G25: =G24-SALES!G24+PURCHASE!G24 -> 208 | H25: =H24-SALES!H24+PURCHASE!H24 -> 152 | I25: =I24-SALES!I24+PURCHASE!I24 -> 98 | J25: 0 | K25: =K24-SALES!K24+PURCHASE!K24 -> 19 | L25: =SUM(B25:K25) -> 1873 | M25: =L25/10 -> 187.3 | N25: =DATE(2023,4,23) -> 45039
A26: =DATE(2023,4,24) -> 45040 | B26: =B25-SALES!B25+PURCHASE!B25 -> 460 | C26: =C25-SALES!C25+PURCHASE!C25 -> 266 | D26: =D25-SALES!D25+PURCHASE!D25 -> 80 | E26: =E25-SALES!E25+PURCHASE!E25 -> 38 | F26: =F25-SALES!F25+PURCHASE!F25 -> 60 | G26: =G25-SALES!G25+PURCHASE!G25 -> 108 | H26: =H25-SALES!H25+PURCHASE!H25 -> 92 | I26: =I25-SALES!I25+PURCHASE!I25 -> 78 | J26: 0 | K26: =K25-SALES!K25+PURCHASE!K25 -> 9 | L26: =SUM(B26:K26) -> 1191 | M26: =L26/10 -> 119.1 | N26: =DATE(2023,4,24) -> 45040
A27: =DATE(2023,4,25) -> 45041 | B27: =B26-SALES!B26+PURCHASE!B26 -> 730 | C27: =C26-SALES!C26+PURCHASE!C26 -> 170 | D27: =D26-SALES!D26+PURCHASE!D26 -> 100 | E27: =E26-SALES!E26+PURCHASE!E26 -> 70 | F27: =F26-SALES!F26+PURCHASE!F26 -> 86 | G27: =G26-SALES!G26+PURCHASE!G26 -> 154 | H27: =H26-SALES!H26+PURCHASE!H26 -> 116 | I27: =I26-SALES!I26+PURCHASE!I26 -> 56 | J27: 0 | K27: =K26-SALES!K26+PURCHASE!K26 -> 18 | L27: =SUM(B27:K27) -> 1500 | M27: =L27/10 -> 150 | N27: =DATE(2023,4,25) -> 45041
A28: =DATE(2023,4,26) -> 45042 | B28: =B27-SALES!B27+PURCHASE!B27 -> 570 | C28: =C27-SALES!C27+PURCHASE!C27 -> 110 | D28: =D27-SALES!D27+PURCHASE!D27 -> 78 | E28: =E27-SALES!E27+PURCHASE!E27 -> 60 | F28: =F27-SALES!F27+PURCHASE!F27 -> 70 | G28: =G27-SALES!G27+PURCHASE!G27 -> 114 | H28: =H27-SALES!H27+PURCHASE!H27 -> 94 | I28: =I27-SALES!I27+PURCHASE!I27 -> 36 | J28: 0 | K28: =K27-SALES!K27+PURCHASE!K27 -> 6 | L28: =SUM(B28:K28) -> 1138 | M28: =L28/10 -> 113.8 | N28: =DATE(2023,4,26) -> 45042
A29: =DATE(2023,4,27) -> 45043 | B29: =B28-SALES!B28+PURCHASE!B28 -> 500 | C29: =C28-SALES!C28+PURCHASE!C28 -> 94 | D29: =D28-SALES!D28+PURCHASE!D28 -> 66 | E29: =E28-SALES!E28+PURCHASE!E28 -> 52 | F29: =F28-SALES!F28+PURCHASE!F28 -> 62 | G29: =G28-SALES!G28+PURCHASE!G28 -> 102 | H29: =H28-SALES!H28+PURCHASE!H28 -> 88 | I29: =I28-SALES!I28+PURCHASE!I28 -> 34 | J29: 0 | K29: =K28-SALES!K28+PURCHASE!K28 -> 6 | L29: =SUM(B29:K29) -> 1004 | M29: =L29/10 -> 100.4 | N29: =DATE(2023,4,27) -> 45043
A30: =DATE(2023,4,28) -> 45044 | B30: =B29-SALES!B29+PURCHASE!B29 -> 890 | C30: =C29-SALES!C29+PURCHASE!C29 -> 214 | D30: =D29-SALES!D29+PURCHASE!D29 -> 48 | E30: =E29-SALES!E29+PURCHASE!E29 -> 42 | F30: =F29-SALES!F29+PURCHASE!F29 -> 46 | G30: =G29-SALES!G29+PURCHASE!G29 -> 90 | H30: =H29-SALES!H29+PURCHASE!H29 -> 128 | I30: =I29-SALES!I29+PURCHASE!I29 -> 30 | J30: 0 | K30: =K29-SALES!K29+PURCHASE!K29 -> 6 | L30: =SUM(B30:K30) -> 1494 | M30: =L30/10 -> 149.4 | N30: =DATE(2023,4,28) -> 45044
A31: =DATE(2023,4,29) -> 45045 | B31: =B30-SALES!B30+PURCHASE!B30 -> 630 | C31: =C30-SALES!C30+PURCHASE!C30 -> 154 | D31: =D30-SALES!D30+PURCHASE!D30 -> 68 | E31: =E30-SALES!E30+PURCHASE!E30 -> 58 | F31: =F30-SALES!F30+PURCHASE!F30 -> 82 | G31: =G30-SALES!G30+PURCHASE!G30 -> 72 | H31: =H30-SALES!H30+PURCHASE!H30 -> 100 | I31: =I30-SALES!I30+PURCHASE!I30 -> 22 | J31: 0 | K31: =K30-SALES!K30+PURCHASE!K30 -> 10 | L31: =SUM(B31:K31) -> 1196 | M31: =L31/10 -> 119.6 | N31: =DATE(2023,4,29) -> 45045
A32: =DATE(2023,4,30) -> 45046 | B32: =B31-SALES!B31+PURCHASE!B31 -> 470 | C32: =C31-SALES!C31+PURCHASE!C31 -> 130 | D32: =D31-SALES!D31+PURCHASE!D31 -> 54 | E32: =E31-SALES!E31+PURCHASE!E31 -> 42 | F32: =F31-SALES!F31+PURCHASE!F31 -> 64 | G32: =G31-SALES!G31+PURCHASE!G31 -> 62 | H32: =H31-SALES!H31+PURCHASE!H31 -> 80 | I32: =I31-SALES!I31+PURCHASE!I31 -> 18 | J32: 0 | K32: =K31-SALES!K31+PURCHASE!K31 -> 8 | L32: =SUM(B32:K32) -> 928 | M32: =L32/10 -> 92.8 | N32: =DATE(2023,4,30) -> 45046
A33: =DATE(2023,4,31) -> 45047 | B33: =B32-SALES!B32+PURCHASE!B32 -> 314 | C33: =C32-SALES!C32+PURCHASE!C32 -> 104 | D33: =D32-SALES!D32+PURCHASE!D32 -> 38 | E33: =E32-SALES!E32+PURCHASE!E32 -> 32 | F33: =F32-SALES!F32+PURCHASE!F32 -> 52 | G33: =G32-SALES!G32+PURCHASE!G32 -> 48 | H33: =H32-SALES!H32+PURCHASE!H32 -> 58 | I33: =I32-SALES!I32+PURCHASE!I32 -> 16 | J33: 0 | K33: =K32-SALES!K32+PURCHASE!K32 -> 8 | L33: =SUM(B33:K33) -> 670 | M33: =L33/10 -> 67 | N33: =DATE(2023,4,31) -> 45047
B34: =AVERAGE(B3:B33) -> 497.35484 | C34: =AVERAGE(C3:C33) -> 187.09677 | D34: =AVERAGE(D3:D33) -> 54.322581 | E34: =AVERAGE(E3:E33) -> 45.225806 | F34: =AVERAGE(F3:F33) -> 63.483871 | G34: =AVERAGE(G3:G33) -> 103.09677 | H34: =AVERAGE(H3:H33) -> 78.580645 | I34: =AVERAGE(I3:I33) -> 30.064516 | ... K34: =AVERAGE(K3:K33) -> 11.935484 | L34: AVERAGE INVENTORY | M34: =SUM(M3:M33)/31 -> 107.11613
L35: AVG. INVENTORY(IN Rs.) | M35: =M34*PURCHASE!L35 -> 18524.857
B36: RICE | C36: ATTA | D36: TOOR DAL | E36: MOONG DAL | F36: URAD DAL | G36: SUGAR | H36: COOKING OIL | I36: GHEE | J36: MILK & DAIRY | K36: DRY FRUITS
B37: 497.35484 | C37: 187.09677 | D37: 54.322581 | E37: 45.225806 | F37: 63.483871 | G37: 103.09677 | H37: 78.580645 | I37: 30.064516 | J37: 0 | K37: 11.935484
C38: INVENTORY TRENDS

Sheet Profit  Loss
B1: RICE | C1: ATTA | D1: TOOR DAL | E1: MOONG DAL | F1: URAD DAL | G1: SUGAR | H1: COOKING OIL | I1: GHEE | J1: MILK & DAIRY | K1: DRY FRUITS
A2: Avg Purchase Price | B2: 40.122581 | C2: 37.898065 | D2: 96.065806 | E2: 100.04516 | F2: 105.94839 | G2: 41.48129 | H2: 142.33419 | I2: 391.67419 | J2: 56.877419 | K2: 716.97097
A3: Avg Selling Price | B3: 44.580645 | C3: 41.193548 | D3: 104.41935 | E3: 111.16129 | F3: 115.16129 | G3: 44.129032 | H3: 151.41935 | I3: 435.19355 | J3: 59.870968 | K3: 874.35484
A4: Avg Profit | B4: =B3-B2 -> 4.4580645 | C4: =C3-C2 -> 3.2954839 | D4: =D3-D2 -> 8.3535484 | E4: =E3-E2 -> 11.116129 | F4: =F3-F2 -> 9.2129032 | G4: =G3-G2 -> 2.6477419 | H4: =H3-H2 -> 9.0851613 | I4: =I3-I2 -> 43.519355 | ... K4: =K3-K2 -> 157.38387
B5: RICE | C5: ATTA | D5: TOOR DAL | E5: MOONG DAL | F5: URAD DAL | G5: SUGAR | H5: COOKING OIL | I5: GHEE | J5: MILK & DAIRY | K5: DRY FRUITS
A7: PRODUCT | B7: P/L | C7: REVENUE (SALES) | D7: % OF TOTAL PROFIT | E7: % OF TOTAL REVENUE | F7: PROFIT MARGIN %
A8: RICE | B8: =SALES!V34-PURCHASE!V37 -> 20144.2 | C8: 140152 | D8: =B8/B$18 -> 0.25792889 | E8: =C8/C$18 -> 0.19033599 | F8: =B4/B3 -> 0.1
A9: ATTA | B9: =SALES!W34-PURCHASE!W37 -> 5105.68 | C9: 52482 | D9: =B9/B$18 -> 0.065373774 | E9: =C9/C$18 -> 0.07127414 | F9: =C4/C3 -> 0.08
A10: TOOR DAL | B10: =SALES!X34-PURCHASE!X37 -> 4964.4 | C10: 46116 | D10: =B10/B$18 -> 0.063564807 | E10: =C10/C$18 -> 0.062628677 | F10: =D4/D3 -> 0.08
A11: MOONG DAL | B11: =SALES!Y34-PURCHASE!Y37 -> 4985.4 | C11: 36786 | D11: =B11/B$18 -> 0.063833694 | E11: =C11/C$18 -> 0.0499579 | F11: =E4/E3 -> 0.1
A12: URAD DAL | B12: =SALES!Z34-PURCHASE!Z37 -> 6313.12 | C12: 59226 | D12: =B12/B$18 -> 0.080833989 | E12: =C12/C$18 -> 0.080432952 | F12: =F4/F3 -> 0.08
A13: SUGAR | B13: =SALES!AA34-PURCHASE!AA37 -> 1890.8 | C13: 32046 | D13: =B13/B$18 -> 0.024210043 | E13: =C13/C$18 -> 0.043520656 | F13: =G4/G3 -> 0.06
A14: COOKING OIL | B14: =SALES!AB34-PURCHASE!AB37 -> 5229.52 | C14: 83994 | D14: =B14/B$18 -> 0.066959437 | E14: =C14/C$18 -> 0.11406959 | F14: =H4/H3 -> 0.06
A15: GHEE | B15: =SALES!AC34-PURCHASE!AC37 -> 9718.5 | C15: 82965 | D15: =B15/B$18 -> 0.12443691 | E15: =C15/C$18 -> 0.11267214 | F15: =I4/I3 -> 0.1
A16: MILK & DAIRY | B16: =SALES!AD34-PURCHASE!AD37 -> 2527 | C16: 116603 | D16: =B16/B$18 -> 0.032356028 | E16: =C16/C$18 -> 0.15835484 | F16: =J4/J3 -> 0.05
A17: DRY FRUITS | B17: =SALES!AE34-PURCHASE!AE37 -> 17221.2 | C17: 85970 | D17: =B17/B$18 -> 0.22050243 | E17: =C17/C$18 -> 0.11675313 | F17: =K4/K3 -> 0.18
B18: =SUM(B8:B17) -> 78099.82 | C18: =SUM(C8:C17) -> 736340 | F18: =AVERAGE(F8:F17) -> 0.089
A47: PRODUCT | B47: % OF TOTAL PROFIT | C47: Cumulative Profit %
A48: RICE | B48: 0.25792889 | C48: =B48 -> 0.25792889
A49: DRY FRUITS | B49: 0.22050243 | C49: =C48+B49 -> 0.47843132
A50: GHEE | B50: 0.12443691 | C50: =C49+B50 -> 0.60286823
A51: URAD DAL | B51: 0.080833989 | C51: =C50+B51 -> 0.68370222
A52: COOKING OIL | B52: 0.066959437 | C52: =C51+B52 -> 0.75066165
A53: ATTA | B53: 0.065373774 | C53: =C52+B53 -> 0.81603543
A54: MOONG DAL | B54: 0.063833694 | C54: =C53+B54 -> 0.87986912
A55: TOOR DAL | B55: 0.063564807 | C55: =C54+B55 -> 0.94343393
A56: MILK & DAIRY | B56: 0.032356028 | C56: =C55+B56 -> 0.97578996
